Workbook
Name VOTI: BASEDATI!$C$4:$H$4
Name VOTI_ESITO: BASEDATI!$C$5:$H$5

Sheet DE ANTONI Mattia
A1: SCHEDA DI AUTOVALUTAZIONE PERFORMANCE
A2: DE ANTONI Mattia | E2: D.NASCITA | F2: STAGIONE | G2: VALUTAZIONE GENERALE | H2: =B5 -> 45778 | I2: =C8 -> 45901 | J2: =D8 -> 45992 | K2: MEDIA
E3: 41082 | F3: 2025/2026 | H3: =IFERROR(AVERAGE(H4:H9),0) -> 59.817128 | I3: =IFERROR(AVERAGE(I4:I9),0) -> 10.91729 | J3: =IFERROR(AVERAGE(J4:J9),0) -> 11.368221
A4: #VALUE! | B4: PESO (kg) | E4: PIEDE FORTE | F4: PIEDE DEBOLE | G4: FISICA | H4: =B11 -> 65 | I4: =C11 -> 0 | J4: =D11 -> 0 | K4: =IFERROR(AVERAGEIF(H4:J4,">0"),0) -> 65 | L4: =LEFT(G4,3) -> FIS
B5: 45778 | C5: 45901 | D5: 45992 | E5: Dx | F5: Sufficiente | G5: TATTICA | H5: =B19 -> 75 | I5: =C19 -> 0 | J5: =D19 -> 0 | K5: =IFERROR(AVERAGEIF(H5:J5,">0"),0) -> 75 | L5: =LEFT(G5,3) -> TAT
B6: 44 | C6: 46 | D6: 47.9 | E6: RUOLO | F6: ATTITUDINE | G6: TECNICA | H6: =H11 -> 70 | I6: =I11 -> 0 | J6: =J11 -> 0 | K6: =IFERROR(AVERAGEIF(H6:J6,">0"),0) -> 70 | L6: =LEFT(G6,3) -> TEC
B7: ALTEZZA (cm) | E7: Portiere | F7: Portiere | G7: PSICOLOGIA | H7: =H19 -> 75 | I7: =I19 -> 0 | J7: =J19 -> 0 | K7: =IFERROR(AVERAGEIF(H7:J7,">0"),0) -> 75 | L7: =LEFT(G7,3) -> PSI
B8: =B5 -> 45778 | C8: =C5 -> 45901 | D8: =D5 -> 45992 | E8: BMI | F8: MORFOLOGIA | G8: BMIx3 | H8: =IF(IFERROR(B6/(B9/100*B9/100),0)*3>70,120-IFERROR(B6/(B9/100*B9/100),0)*3,IFERROR(B6/(B9/100*B9/100),0)*3) -> 54.942768 | I8: =IF(IFERROR(C6/(C9/100*C9/100),0)*3>70,120-IFERROR(C6/(C9/100*C9/100),0)*3,IFERROR(C6/(C9/100*C9/100),0)*3) -> 54.586448 | J8: =IF(IFERROR(D6/(D9/100*D9/100),0)*3>70,120-IFERROR(D6/(D9/100*D9/100),0)*3,IFERROR(D6/(D9/100*D9/100),0)*3) -> 56.841106 | K8: =IFERROR(ROUND(AVERAGEIF(H8:J8,">0"),0),0) -> 55 | L8: BMI
B9: 155 | C9: 159 | D9: 159 | E9: =_xlfn.XLOOKUP(IF(ROUND((AVERAGEIF(B6:D6,">0")/(AVERAGEIF(B9:D9,">0")*AVERAGEIF(B9:D9,">0")/10000)*3)/3,0)>70,120-ROUND((AVERAGEIF(B6:D6,">0")/(AVERAGEIF(B9:D9,">0")*AVERAGEIF(B9:D9,">0")/10000)*3)/3,0),ROUND((AVERAGEIF(B6:D6,">0")/(AVERAGEIF(B9:D9,">0")*AVERAGEIF(B9:D9,">0")/10000)*3)/3,0)),BASEDATI!B15:B21,BASEDATI!C15:C21,,1) -> Sottopeso | F9: Brevilineo | G9: ILLINOIS | H9: 18.96
A10: VALUTAZIONE FISICA | B10: =B8 -> 45778 | C10: =C8 -> 45901 | D10: =D8 -> 45992 | E10: MEDIA | G10: VALUTAZIONE TECNICA | H10: =H2 -> 45778 | I10: =I2 -> 45901 | J10: =J2 -> 45992 | K10: MEDIA
B11: =SUM(HLOOKUP(B12,BASEDATI!$C$4:$H$5,2,FALSE),HLOOKUP(B13,BASEDATI!$C$4:$H$5,2,FALSE),HLOOKUP(B14,BASEDATI!$C$4:$H$5,2,FALSE),HLOOKUP(B15,BASEDATI!$C$4:$H$5,2,FALSE),HLOOKUP(B16,BASEDATI!$C$4:$H$5,2,FALSE),HLOOKUP(B17,BASEDATI!$C$4:$H$5,2,FALSE))/COUNTA(B12:B17) -> 65 | C11: =IFERROR(SUM(HLOOKUP(C12,BASEDATI!$C$4:$H$5,2,FALSE),HLOOKUP(C13,BASEDATI!$C$4:$H$5,2,FALSE),HLOOKUP(C14,BASEDATI!$C$4:$H$5,2,FALSE),HLOOKUP(C15,BASEDATI!$C$4:$H$5,2,FALSE),HLOOKUP(C16,BASEDATI!$C$4:$H$5,2,FALSE),HLOOKUP(C17,BASEDATI!$C$4:$H$5,2,FALSE))/COUNTA(C12:C17),0) -> 0 | D11: =IFERROR(SUM(HLOOKUP(D12,BASEDATI!$C$4:$H$5,2,FALSE),HLOOKUP(D13,BASEDATI!$C$4:$H$5,2,FALSE),HLOOKUP(D14,BASEDATI!$C$4:$H$5,2,FALSE),HLOOKUP(D15,BASEDATI!$C$4:$H$5,2,FALSE),HLOOKUP(D16,BASEDATI!$C$4:$H$5,2,FALSE),HLOOKUP(D17,BASEDATI!$C$4:$H$5,2,FALSE))/COUNTA(D12:D17),0) -> 0 | H11: =SUM(HLOOKUP(H12,BASEDATI!$C$4:$H$5,2,FALSE),HLOOKUP(H13,BASEDATI!$C$4:$H$5,2,FALSE),HLOOKUP(H14,BASEDATI!$C$4:$H$5,2,FALSE),HLOOKUP(H15,BASEDATI!$C$4:$H$5,2,FALSE),HLOOKUP(H16,BASEDATI!$C$4:$H$5,2,FALSE),HLOOKUP(H17,BASEDATI!$C$4:$H$5,2,FALSE))/COUNTA(H12:H17) -> 70 | I11: =IFERROR(SUM(HLOOKUP(I12,BASEDATI!$C$4:$H$5,2,FALSE),HLOOKUP(I13,BASEDATI!$C$4:$H$5,2,FALSE),HLOOKUP(I14,BASEDATI!$C$4:$H$5,2,FALSE),HLOOKUP(I15,BASEDATI!$C$4:$H$5,2,FALSE),HLOOKUP(I16,BASEDATI!$C$4:$H$5,2,FALSE),HLOOKUP(I17,BASEDATI!$C$4:$H$5,2,FALSE))/COUNTA(I12:I17),0) -> 0 | J11: =IFERROR(SUM(HLOOKUP(J12,BASEDATI!$C$4:$H$5,2,FALSE),HLOOKUP(J13,BASEDATI!$C$4:$H$5,2,FALSE),HLOOKUP(J14,BASEDATI!$C$4:$H$5,2,FALSE),HLOOKUP(J15,BASEDATI!$C$4:$H$5,2,FALSE),HLOOKUP(J16,BASEDATI!$C$4:$H$5,2,FALSE),HLOOKUP(J17,BASEDATI!$C$4:$H$5,2,FALSE))/COUNTA(J12:J17),0) -> 0
A12: Forza | B12: Buono | E12: =SUM(IFERROR(HLOOKUP(B12,BASEDATI!$C$4:$H$5,2,FALSE),0),IFERROR(HLOOKUP(C12,BASEDATI!$C$4:$H$5,2,FALSE),0),IFERROR(HLOOKUP(D12,BASEDATI!$C$4:$H$5,2,FALSE),0))/COUNTA(B12:D12) -> 70 | F12: =LEFT(A12,3) -> For | G12: Tuffo | H12: Buono | K12: =SUM(IFERROR(HLOOKUP(H12,BASEDATI!$C$4:$H$5,2,FALSE),0),IFERROR(HLOOKUP(I12,BASEDATI!$C$4:$H$5,2,FALSE),0),IFERROR(HLOOKUP(J12,BASEDATI!$C$4:$H$5,2,FALSE),0))/COUNTA(H12:J12) -> 70 | L12: =LEFT(G12,3) -> Tuf
A13: Velocità | B13: Sufficiente | E13: =SUM(IFERROR(HLOOKUP(B13,BASEDATI!$C$4:$H$5,2,FALSE),0),IFERROR(HLOOKUP(C13,BASEDATI!$C$4:$H$5,2,FALSE),0),IFERROR(HLOOKUP(D13,BASEDATI!$C$4:$H$5,2,FALSE),0))/COUNTA(B13:D13) -> 60 | F13: =LEFT(A13,3) -> Vel | G13: Spaccata | H13: Buono | K13: =SUM(IFERROR(HLOOKUP(H13,BASEDATI!$C$4:$H$5,2,FALSE),0),IFERROR(HLOOKUP(I13,BASEDATI!$C$4:$H$5,2,FALSE),0),IFERROR(HLOOKUP(J13,BASEDATI!$C$4:$H$5,2,FALSE),0))/COUNTA(H13:J13) -> 70 | L13: =LEFT(G13,3) -> Spa
A14: Resistenza | B14: Buono | E14: =SUM(IFERROR(HLOOKUP(B14,BASEDATI!$C$4:$H$5,2,FALSE),0),IFERROR(HLOOKUP(C14,BASEDATI!$C$4:$H$5,2,FALSE),0),IFERROR(HLOOKUP(D14,BASEDATI!$C$4:$H$5,2,FALSE),0))/COUNTA(B14:D14) -> 70 | F14: =LEFT(A14,3) -> Res | G14: Uscita | H14: Ottimo | K14: =SUM(IFERROR(HLOOKUP(H14,BASEDATI!$C$4:$H$5,2,FALSE),0),IFERROR(HLOOKUP(I14,BASEDATI!$C$4:$H$5,2,FALSE),0),IFERROR(HLOOKUP(J14,BASEDATI!$C$4:$H$5,2,FALSE),0))/COUNTA(H14:J14) -> 80 | L14: =LEFT(G14,3) -> Usc
A15: Coordinazione | B15: Buono | E15: =SUM(IFERROR(HLOOKUP(B15,BASEDATI!$C$4:$H$5,2,FALSE),0),IFERROR(HLOOKUP(C15,BASEDATI!$C$4:$H$5,2,FALSE),0),IFERROR(HLOOKUP(D15,BASEDATI!$C$4:$H$5,2,FALSE),0))/COUNTA(B15:D15) -> 70 | F15: =LEFT(A15,3) -> Coo | G15: Presa | H15: Buono | K15: =SUM(IFERROR(HLOOKUP(H15,BASEDATI!$C$4:$H$5,2,FALSE),0),IFERROR(HLOOKUP(I15,BASEDATI!$C$4:$H$5,2,FALSE),0),IFERROR(HLOOKUP(J15,BASEDATI!$C$4:$H$5,2,FALSE),0))/COUNTA(H15:J15) -> 70 | L15: =LEFT(G15,3) -> Pre
A16: Rapidità | B16: Sufficiente | E16: =SUM(IFERROR(HLOOKUP(B16,BASEDATI!$C$4:$H$5,2,FALSE),0),IFERROR(HLOOKUP(C16,BASEDATI!$C$4:$H$5,2,FALSE),0),IFERROR(HLOOKUP(D16,BASEDATI!$C$4:$H$5,2,FALSE),0))/COUNTA(B16:D16) -> 60 | F16: =LEFT(A16,3) -> Rap | G16: Rinvio con mani | H16: Buono | K16: =SUM(IFERROR(HLOOKUP(H16,BASEDATI!$C$4:$H$5,2,FALSE),0),IFERROR(HLOOKUP(I16,BASEDATI!$C$4:$H$5,2,FALSE),0),IFERROR(HLOOKUP(J16,BASEDATI!$C$4:$H$5,2,FALSE),0))/COUNTA(H16:J16) -> 70 | L16: =LEFT(G16,3) -> Rin
A17: Recupero | B17: Sufficiente | E17: =SUM(IFERROR(HLOOKUP(B17,BASEDATI!$C$4:$H$5,2,FALSE),0),IFERROR(HLOOKUP(C17,BASEDATI!$C$4:$H$5,2,FALSE),0),IFERROR(HLOOKUP(D17,BASEDATI!$C$4:$H$5,2,FALSE),0))/COUNTA(B17:D17) -> 60 | F17: =LEFT(A17,3) -> Rec | G17: Passagio | H17: Sufficiente | K17: =SUM(IFERROR(HLOOKUP(H17,BASEDATI!$C$4:$H$5,2,FALSE),0),IFERROR(HLOOKUP(I17,BASEDATI!$C$4:$H$5,2,FALSE),0),IFERROR(HLOOKUP(J17,BASEDATI!$C$4:$H$5,2,FALSE),0))/COUNTA(H17:J17) -> 60 | L17: =LEFT(G17,3) -> Pas
A18: VALUTAZIONE TATTICA | B18: =B10 -> 45778 | C18: =C10 -> 45901 | D18: =D10 -> 45992 | E18: MEDIA | G18: VALUTAZIONE PISICOLOGICA | H18: =H10 -> 45778 | I18: =I10 -> 45901 | J18: =J10 -> 45992 | K18: MEDIA
B19: =SUM(HLOOKUP(B20,BASEDATI!$C$4:$H$5,2,FALSE),HLOOKUP(B21,BASEDATI!$C$4:$H$5,2,FALSE),HLOOKUP(B22,BASEDATI!$C$4:$H$5,2,FALSE),HLOOKUP(B23,BASEDATI!$C$4:$H$5,2,FALSE),HLOOKUP(B24,BASEDATI!$C$4:$H$5,2,FALSE),HLOOKUP(B25,BASEDATI!$C$4:$H$5,2,FALSE))/COUNTA(B20:B25) -> 75 | C19: =IFERROR(SUM(HLOOKUP(C20,BASEDATI!$C$4:$H$5,2,FALSE),HLOOKUP(C21,BASEDATI!$C$4:$H$5,2,FALSE),HLOOKUP(C22,BASEDATI!$C$4:$H$5,2,FALSE),HLOOKUP(C23,BASEDATI!$C$4:$H$5,2,FALSE),HLOOKUP(C24,BASEDATI!$C$4:$H$5,2,FALSE),HLOOKUP(C25,BASEDATI!$C$4:$H$5,2,FALSE))/COUNTA(C20:C25),0) -> 0 | D19: =IFERROR(SUM(HLOOKUP(D20,BASEDATI!$C$4:$H$5,2,FALSE),HLOOKUP(D21,BASEDATI!$C$4:$H$5,2,FALSE),HLOOKUP(D22,BASEDATI!$C$4:$H$5,2,FALSE),HLOOKUP(D23,BASEDATI!$C$4:$H$5,2,FALSE),HLOOKUP(D24,BASEDATI!$C$4:$H$5,2,FALSE),HLOOKUP(D25,BASEDATI!$C$4:$H$5,2,FALSE))/COUNTA(D20:D25),0) -> 0 | H19: =SUM(HLOOKUP(H20,BASEDATI!$C$4:$H$5,2,FALSE),HLOOKUP(H21,BASEDATI!$C$4:$H$5,2,FALSE),HLOOKUP(H22,BASEDATI!$C$4:$H$5,2,FALSE),HLOOKUP(H23,BASEDATI!$C$4:$H$5,2,FALSE),HLOOKUP(H24,BASEDATI!$C$4:$H$5,2,FALSE),HLOOKUP(H25,BASEDATI!$C$4:$H$5,2,FALSE))/COUNTA(H20:H25) -> 75 | I19: =IFERROR(SUM(HLOOKUP(I20,BASEDATI!$C$4:$H$5,2,FALSE),HLOOKUP(I21,BASEDATI!$C$4:$H$5,2,FALSE),HLOOKUP(I22,BASEDATI!$C$4:$H$5,2,FALSE),HLOOKUP(I23,BASEDATI!$C$4:$H$5,2,FALSE),HLOOKUP(I24,BASEDATI!$C$4:$H$5,2,FALSE),HLOOKUP(I25,BASEDATI!$C$4:$H$5,2,FALSE))/COUNTA(I20:I25),0) -> 0 | J19: =IFERROR(SUM(HLOOKUP(J20,BASEDATI!$C$4:$H$5,2,FALSE),HLOOKUP(J21,BASEDATI!$C$4:$H$5,2,FALSE),HLOOKUP(J22,BASEDATI!$C$4:$H$5,2,FALSE),HLOOKUP(J23,BASEDATI!$C$4:$H$5,2,FALSE),HLOOKUP(J24,BASEDATI!$C$4:$H$5,2,FALSE),HLOOKUP(J25,BASEDATI!$C$4:$H$5,2,FALSE))/COUNTA(J20:J25),0) -> 0
A20: Piazzamento | B20: Ottimo | E20: =SUM(IFERROR(HLOOKUP(B20,BASEDATI!$C$4:$H$5,2,FALSE),0),IFERROR(HLOOKUP(C20,BASEDATI!$C$4:$H$5,2,FALSE),0),IFERROR(HLOOKUP(D20,BASEDATI!$C$4:$H$5,2,FALSE),0))/COUNTA(B20:D20) -> 80 | F20: =LEFT(A20,3) -> Pia | G20: Leadership | H20: Ottimo | K20: =SUM(IFERROR(HLOOKUP(H20,BASEDATI!$C$4:$H$5,2,FALSE),0),IFERROR(HLOOKUP(I20,BASEDATI!$C$4:$H$5,2,FALSE),0),IFERROR(HLOOKUP(J20,BASEDATI!$C$4:$H$5,2,FALSE),0))/COUNTA(H20:J20) -> 80 | L20: =LEFT(G20,3) -> Lea
A21: Cambio di posizione | B21: Buono | E21: =SUM(IFERROR(HLOOKUP(B21,BASEDATI!$C$4:$H$5,2,FALSE),0),IFERROR(HLOOKUP(C21,BASEDATI!$C$4:$H$5,2,FALSE),0),IFERROR(HLOOKUP(D21,BASEDATI!$C$4:$H$5,2,FALSE),0))/COUNTA(B21:D21) -> 70 | F21: =LEFT(A21,3) -> Cam | G21: Apprendimento | H21: Buono | K21: =SUM(IFERROR(HLOOKUP(H21,BASEDATI!$C$4:$H$5,2,FALSE),0),IFERROR(HLOOKUP(I21,BASEDATI!$C$4:$H$5,2,FALSE),0),IFERROR(HLOOKUP(J21,BASEDATI!$C$4:$H$5,2,FALSE),0))/COUNTA(H21:J21) -> 70 | L21: =LEFT(G21,3) -> App
A22: Difesa della porta | B22: Buono | E22: =SUM(IFERROR(HLOOKUP(B22,BASEDATI!$C$4:$H$5,2,FALSE),0),IFERROR(HLOOKUP(C22,BASEDATI!$C$4:$H$5,2,FALSE),0),IFERROR(HLOOKUP(D22,BASEDATI!$C$4:$H$5,2,FALSE),0))/COUNTA(B22:D22) -> 70 | F22: =LEFT(A22,3) -> Dif | G22: Impegno | H22: Ottimo | K22: =SUM(IFERROR(HLOOKUP(H22,BASEDATI!$C$4:$H$5,2,FALSE),0),IFERROR(HLOOKUP(I22,BASEDATI!$C$4:$H$5,2,FALSE),0),IFERROR(HLOOKUP(J22,BASEDATI!$C$4:$H$5,2,FALSE),0))/COUNTA(H22:J22) -> 80 | L22: =LEFT(G22,3) -> Imp
A23: Guida della difesa | B23: Buono | E23: =SUM(IFERROR(HLOOKUP(B23,BASEDATI!$C$4:$H$5,2,FALSE),0),IFERROR(HLOOKUP(C23,BASEDATI!$C$4:$H$5,2,FALSE),0),IFERROR(HLOOKUP(D23,BASEDATI!$C$4:$H$5,2,FALSE),0))/COUNTA(B23:D23) -> 70 | F23: =LEFT(A23,3) -> Gui | G23: Resilienza | H23: Buono | K23: =SUM(IFERROR(HLOOKUP(H23,BASEDATI!$C$4:$H$5,2,FALSE),0),IFERROR(HLOOKUP(I23,BASEDATI!$C$4:$H$5,2,FALSE),0),IFERROR(HLOOKUP(J23,BASEDATI!$C$4:$H$5,2,FALSE),0))/COUNTA(H23:J23) -> 70 | L23: =LEFT(G23,3) -> Res
A24: Lettura situazione | B24: Ottimo | E24: =SUM(IFERROR(HLOOKUP(B24,BASEDATI!$C$4:$H$5,2,FALSE),0),IFERROR(HLOOKUP(C24,BASEDATI!$C$4:$H$5,2,FALSE),0),IFERROR(HLOOKUP(D24,BASEDATI!$C$4:$H$5,2,FALSE),0))/COUNTA(B24:D24) -> 80 | F24: =LEFT(A24,3) -> Let | G24: Emotività | H24: Buono | K24: =SUM(IFERROR(HLOOKUP(H24,BASEDATI!$C$4:$H$5,2,FALSE),0),IFERROR(HLOOKUP(I24,BASEDATI!$C$4:$H$5,2,FALSE),0),IFERROR(HLOOKUP(J24,BASEDATI!$C$4:$H$5,2,FALSE),0))/COUNTA(H24:J24) -> 70 | L24: =LEFT(G24,3) -> Emo
A25: Transizione | B25: Ottimo | E25: =SUM(IFERROR(HLOOKUP(B25,BASEDATI!$C$4:$H$5,2,FALSE),0),IFERROR(HLOOKUP(C25,BASEDATI!$C$4:$H$5,2,FALSE),0),IFERROR(HLOOKUP(D25,BASEDATI!$C$4:$H$5,2,FALSE),0))/COUNTA(B25:D25) -> 80 | F25: =LEFT(A25,3) -> Tra | G25: Rispetto | H25: Ottimo | K25: =SUM(IFERROR(HLOOKUP(H25,BASEDATI!$C$4:$H$5,2,FALSE),0),IFERROR(HLOOKUP(I25,BASEDATI!$C$4:$H$5,2,FALSE),0),IFERROR(HLOOKUP(J25,BASEDATI!$C$4:$H$5,2,FALSE),0))/COUNTA(H25:J25) -> 80 | L25: =LEFT(G25,3) -> Ris
A26: SCHEDA DI VALUTAZIONE PERFORMANCE
A27: DE ANTONI Mattia | E27: D.NASCITA | F27: STAGIONE | G27: VALUTAZIONE GENERALE | H27: =B30 -> 45778 | I27: =C33 -> 45901 | J27: =D33 -> 45992 | K27: MEDIA
E28: 41082 | F28: 2025/2026 | H28: =IFERROR(AVERAGE(H29:H34),0) -> 58.219255 | I28: =IFERROR(AVERAGE(I29:I34),0) -> 11.391954 | J28: =IFERROR(AVERAGE(J29:J34),0) -> 0
A29: #VALUE! | B29: PESO (kg) | E29: PIEDE FORTE | F29: PIEDE DEBOLE | G29: FISICA | H29: =B36 -> 65 | I29: =C36 -> 0 | J29: =D36 -> 0 | K29: =IFERROR(AVERAGEIF(H29:J29,">0"),0) -> 65 | L29: =LEFT(G29,3) -> FIS
B30: =B5 -> 45778 | C30: =C5 -> 45901 | D30: =D5 -> 45992 | E30: Dx | F30: Sufficiente | G30: TATTICA | H30: =B44 -> 68.333333 | I30: =C44 -> 0 | J30: =D44 -> 0 | K30: =IFERROR(AVERAGEIF(H30:J30,">0"),0) -> 68.333333 | L30: =LEFT(G30,3) -> TAT
B31: 47 | C31: 48 | E31: RUOLO | F31: ATTITUDINE | G31: TECNICA | H31: =H36 -> 66.666667 | I31: =I36 -> 0 | J31: =J36 -> 0 | K31: =IFERROR(AVERAGEIF(H31:J31,">0"),0) -> 66.666667 | L31: =LEFT(G31,3) -> TEC
B32: ALTEZZA (cm) | E32: Portiere | F32: Portiere | G32: PSICOLOGIA | H32: =H44 -> 71.666667 | I32: =I44 -> 0 | J32: =J44 -> 0 | K32: =IFERROR(AVERAGEIF(H32:J32,">0"),0) -> 71.666667 | L32: =LEFT(G32,3) -> PSI
B33: =B30 -> 45778 | C33: =C30 -> 45901 | D33: =D30 -> 45992 | E33: CORPORATURA | F33: MORFOLOGIA | G33: BMIx3 | H33: =IF(IFERROR(B31/(B34/100*B34/100),0)*3>70,120-IFERROR(B31/(B34/100*B34/100),0)*3,IFERROR(B31/(B34/100*B34/100),0)*3) -> 58.688866 | I33: =IF(IFERROR(C31/(C34/100*C34/100),0)*3>70,120-IFERROR(C31/(C34/100*C34/100),0)*3,IFERROR(C31/(C34/100*C34/100),0)*3) -> 56.959772 | J33: =IF(IFERROR(D31/(D34/100*D34/100),0)*3>70,120-IFERROR(D31/(D34/100*D34/100),0)*3,IFERROR(D31/(D34/100*D34/100),0)*3) -> 0 | K33: =IFERROR(AVERAGEIF(H33:J33,">0"),0) -> 57.824319 | L33: =LEFT(G33,3) -> BMI
B34: 155 | C34: 159 | E34: =E9 -> Sottopeso | F34: Brevilineo | G34: ILLINOIS | H34: 18.96 | L34: =LEFT(G34,3) -> ILL
A35: VALUTAZIONE FISICA | B35: =B33 -> 45778 | C35: =C33 -> 45901 | D35: =D33 -> 45992 | E35: MEDIA | G35: VALUTAZIONE TECNICA | H35: =H27 -> 45778 | I35: =I27 -> 45901 | J35: =J27 -> 45992 | K35: MEDIA | L35: MEDIA
B36: =IFERROR(SUM(HLOOKUP(B37,BASEDATI!$C$4:$H$5,2,FALSE),HLOOKUP(B38,BASEDATI!$C$4:$H$5,2,FALSE),HLOOKUP(B39,BASEDATI!$C$4:$H$5,2,FALSE),HLOOKUP(B40,BASEDATI!$C$4:$H$5,2,FALSE),HLOOKUP(B41,BASEDATI!$C$4:$H$5,2,FALSE),HLOOKUP(B42,BASEDATI!$C$4:$H$5,2,FALSE))/COUNTA(B37:B42),0) -> 65 | C36: =IFERROR(SUM(HLOOKUP(C37,BASEDATI!$C$4:$H$5,2,FALSE),HLOOKUP(C38,BASEDATI!$C$4:$H$5,2,FALSE),HLOOKUP(C39,BASEDATI!$C$4:$H$5,2,FALSE),HLOOKUP(C40,BASEDATI!$C$4:$H$5,2,FALSE),HLOOKUP(C41,BASEDATI!$C$4:$H$5,2,FALSE),HLOOKUP(C42,BASEDATI!$C$4:$H$5,2,FALSE))/COUNTA(C37:C42),0) -> 0 | D36: =IFERROR(SUM(HLOOKUP(D37,BASEDATI!$C$4:$H$5,2,FALSE),HLOOKUP(D38,BASEDATI!$C$4:$H$5,2,FALSE),HLOOKUP(D39,BASEDATI!$C$4:$H$5,2,FALSE),HLOOKUP(D40,BASEDATI!$C$4:$H$5,2,FALSE),HLOOKUP(D41,BASEDATI!$C$4:$H$5,2,FALSE),HLOOKUP(D42,BASEDATI!$C$4:$H$5,2,FALSE))/COUNTA(D37:D42),0) -> 0 | H36: =IFERROR(SUM(HLOOKUP(H37,BASEDATI!$C$4:$H$5,2,FALSE),HLOOKUP(H38,BASEDATI!$C$4:$H$5,2,FALSE),HLOOKUP(H39,BASEDATI!$C$4:$H$5,2,FALSE),HLOOKUP(H40,BASEDATI!$C$4:$H$5,2,FALSE),HLOOKUP(H41,BASEDATI!$C$4:$H$5,2,FALSE),HLOOKUP(H42,BASEDATI!$C$4:$H$5,2,FALSE))/COUNTA(H37:H42),0) -> 66.666667 | I36: =IFERROR(SUM(HLOOKUP(I37,BASEDATI!$C$4:$H$5,2,FALSE),HLOOKUP(I38,BASEDATI!$C$4:$H$5,2,FALSE),HLOOKUP(I39,BASEDATI!$C$4:$H$5,2,FALSE),HLOOKUP(I40,BASEDATI!$C$4:$H$5,2,FALSE),HLOOKUP(I41,BASEDATI!$C$4:$H$5,2,FALSE),HLOOKUP(I42,BASEDATI!$C$4:$H$5,2,FALSE))/COUNTA(I37:I42),0) -> 0 | J36: =IFERROR(SUM(HLOOKUP(J37,BASEDATI!$C$4:$H$5,2,FALSE),HLOOKUP(J38,BASEDATI!$C$4:$H$5,2,FALSE),HLOOKUP(J39,BASEDATI!$C$4:$H$5,2,FALSE),HLOOKUP(J40,BASEDATI!$C$4:$H$5,2,FALSE),HLOOKUP(J41,BASEDATI!$C$4:$H$5,2,FALSE),HLOOKUP(J42,BASEDATI!$C$4:$H$5,2,FALSE))/COUNTA(J37:J42),0) -> 0
A37: Forza | B37: Sufficiente | E37: =SUM(IFERROR(HLOOKUP(B37,BASEDATI!$C$4:$H$5,2,FALSE),0),IFERROR(HLOOKUP(C37,BASEDATI!$C$4:$H$5,2,FALSE),0),IFERROR(HLOOKUP(D37,BASEDATI!$C$4:$H$5,2,FALSE),0))/COUNTA(B37:D37) -> 60 | F37: =LEFT(A37,3) -> For | G37: Tuffo | H37: Sufficiente | K37: =SUM(IFERROR(HLOOKUP(H37,BASEDATI!$C$4:$H$5,2,FALSE),0),IFERROR(HLOOKUP(I37,BASEDATI!$C$4:$H$5,2,FALSE),0),IFERROR(HLOOKUP(J37,BASEDATI!$C$4:$H$5,2,FALSE),0))/COUNTA(H37:J37) -> 60 | L37: =LEFT(G37,3) -> Tuf
A38: Velocità | B38: Sufficiente | E38: =SUM(IFERROR(HLOOKUP(B38,BASEDATI!$C$4:$H$5,2,FALSE),0),IFERROR(HLOOKUP(C38,BASEDATI!$C$4:$H$5,2,FALSE),0),IFERROR(HLOOKUP(D38,BASEDATI!$C$4:$H$5,2,FALSE),0))/COUNTA(B38:D38) -> 60 | F38: =LEFT(A38,3) -> Vel | G38: Spaccata | H38: Buono | K38: =SUM(IFERROR(HLOOKUP(H38,BASEDATI!$C$4:$H$5,2,FALSE),0),IFERROR(HLOOKUP(I38,BASEDATI!$C$4:$H$5,2,FALSE),0),IFERROR(HLOOKUP(J38,BASEDATI!$C$4:$H$5,2,FALSE),0))/COUNTA(H38:J38) -> 70 | L38: =LEFT(G38,3) -> Spa
A39: Resistenza | B39: Sufficiente | E39: =SUM(IFERROR(HLOOKUP(B39,BASEDATI!$C$4:$H$5,2,FALSE),0),IFERROR(HLOOKUP(C39,BASEDATI!$C$4:$H$5,2,FALSE),0),IFERROR(HLOOKUP(D39,BASEDATI!$C$4:$H$5,2,FALSE),0))/COUNTA(B39:D39) -> 60 | F39: =LEFT(A39,3) -> Res | G39: Uscita | H39: Buono | K39: =SUM(IFERROR(HLOOKUP(H39,BASEDATI!$C$4:$H$5,2,FALSE),0),IFERROR(HLOOKUP(I39,BASEDATI!$C$4:$H$5,2,FALSE),0),IFERROR(HLOOKUP(J39,BASEDATI!$C$4:$H$5,2,FALSE),0))/COUNTA(H39:J39) -> 70 | L39: =LEFT(G39,3) -> Usc
A40: Coordinazione | B40: Buono | E40: =SUM(IFERROR(HLOOKUP(B40,BASEDATI!$C$4:$H$5,2,FALSE),0),IFERROR(HLOOKUP(C40,BASEDATI!$C$4:$H$5,2,FALSE),0),IFERROR(HLOOKUP(D40,BASEDATI!$C$4:$H$5,2,FALSE),0))/COUNTA(B40:D40) -> 70 | F40: =LEFT(A40,3) -> Coo | G40: Presa | H40: Buono | K40: =SUM(IFERROR(HLOOKUP(H40,BASEDATI!$C$4:$H$5,2,FALSE),0),IFERROR(HLOOKUP(I40,BASEDATI!$C$4:$H$5,2,FALSE),0),IFERROR(HLOOKUP(J40,BASEDATI!$C$4:$H$5,2,FALSE),0))/COUNTA(H40:J40) -> 70 | L40: =LEFT(G40,3) -> Pre
...

Sheet LOFFREDA Giammaria
A1: SCHEDA DI AUTOVALUTAZIONE PERFORMANCE
A2: LOFFREDA Giammaria | E2: D.NASCITA | F2: STAGIONE | G2: VALUTAZIONE GENERALE | H2: =B5 -> 45778 | I2: =C8 -> 45901 | J2: =D8 -> 45992 | K2: MEDIA
E3: 41217 | F3: 2025/2026 | H3: =IFERROR(AVERAGE(H4:H9),0) -> 56.033022 | I3: =IFERROR(AVERAGE(I4:I9),0) -> 11.390533 | J3: =IFERROR(AVERAGE(J4:J9),0) -> 11.611019
B4: PESO (kg) | E4: PIEDE FORTE | F4: PIEDE DEBOLE | G4: FISICA | H4: =B11 -> 65 | I4: =C11 -> 0 | J4: =D11 -> 0 | K4: =IFERROR(AVERAGEIF(H4:J4,">0"),0) -> 65 | L4: =LEFT(G4,3) -> FIS
B5: 45778 | C5: 45901 | D5: 45992 | E5: Dx | F5: Sufficiente | G5: TATTICA | H5: =B19 -> 65 | I5: =C19 -> 0 | J5: =D19 -> 0 | K5: =IFERROR(AVERAGEIF(H5:J5,">0"),0) -> 65 | L5: =LEFT(G5,3) -> TAT
B6: 45 | C6: 46.2 | D6: 47.7 | E6: RUOLO | F6: ATTITUDINE | G6: TECNICA | H6: =H11 -> 65 | I6: =I11 -> 0 | J6: =J11 -> 0 | K6: =IFERROR(AVERAGEIF(H6:J6,">0"),0) -> 65 | L6: =LEFT(G6,3) -> TEC
B7: ALTEZZA (cm) | E7: Portiere | F7: Portiere | G7: PSICOLOGIA | H7: =H19 -> 66.666667 | I7: =I19 -> 0 | J7: =J19 -> 0 | K7: =IFERROR(AVERAGEIF(H7:J7,">0"),0) -> 66.666667 | L7: =LEFT(G7,3) -> PSI
B8: =B5 -> 45778 | C8: =C5 -> 45901 | D8: =D5 -> 45992 | E8: BMI | F8: MORFOLOGIA | G8: BMIx3 | H8: =IF(IFERROR(B6/(B9/100*B9/100),0)*3>70,120-IFERROR(B6/(B9/100*B9/100),0)*3,IFERROR(B6/(B9/100*B9/100),0)*3) -> 56.191467 | I8: =IF(IFERROR(C6/(C9/100*C9/100),0)*3>70,120-IFERROR(C6/(C9/100*C9/100),0)*3,IFERROR(C6/(C9/100*C9/100),0)*3) -> 56.952663 | J8: =IF(IFERROR(D6/(D9/100*D9/100),0)*3>70,120-IFERROR(D6/(D9/100*D9/100),0)*3,IFERROR(D6/(D9/100*D9/100),0)*3) -> 58.055094 | K8: =IFERROR(ROUND(AVERAGEIF(H8:J8,">0"),0),0) -> 57 | L8: BMI
B9: 155 | C9: 156 | D9: 157 | E9: =_xlfn.XLOOKUP(IF(ROUND((AVERAGEIF(B6:D6,">0")/(AVERAGEIF(B9:D9,">0")*AVERAGEIF(B9:D9,">0")/10000)*3)/3,0)>70,120-ROUND((AVERAGEIF(B6:D6,">0")/(AVERAGEIF(B9:D9,">0")*AVERAGEIF(B9:D9,">0")/10000)*3)/3,0),ROUND((AVERAGEIF(B6:D6,">0")/(AVERAGEIF(B9:D9,">0")*AVERAGEIF(B9:D9,">0")/10000)*3)/3,0)),BASEDATI!B15:B21,BASEDATI!C15:C21,,1) -> Sottopeso | F9: Normolineo | G9: ILLINOIS | H9: 18.34
A10: VALUTAZIONE FISICA | B10: =B8 -> 45778 | C10: =C8 -> 45901 | D10: =D8 -> 45992 | E10: MEDIA | G10: VALUTAZIONE TECNICA | H10: =H2 -> 45778 | I10: =I2 -> 45901 | J10: =J2 -> 45992 | K10: MEDIA
B11: =IFERROR(SUM(HLOOKUP(B12,BASEDATI!$C$4:$H$5,2,FALSE),HLOOKUP(B13,BASEDATI!$C$4:$H$5,2,FALSE),HLOOKUP(B14,BASEDATI!$C$4:$H$5,2,FALSE),HLOOKUP(B15,BASEDATI!$C$4:$H$5,2,FALSE),HLOOKUP(B16,BASEDATI!$C$4:$H$5,2,FALSE),HLOOKUP(B17,BASEDATI!$C$4:$H$5,2,FALSE))/COUNTA(B12:B17),0) -> 65 | C11: =IFERROR(SUM(HLOOKUP(C12,BASEDATI!$C$4:$H$5,2,FALSE),HLOOKUP(C13,BASEDATI!$C$4:$H$5,2,FALSE),HLOOKUP(C14,BASEDATI!$C$4:$H$5,2,FALSE),HLOOKUP(C15,BASEDATI!$C$4:$H$5,2,FALSE),HLOOKUP(C16,BASEDATI!$C$4:$H$5,2,FALSE),HLOOKUP(C17,BASEDATI!$C$4:$H$5,2,FALSE))/COUNTA(C12:C17),0) -> 0 | D11: =IFERROR(SUM(HLOOKUP(D12,BASEDATI!$C$4:$H$5,2,FALSE),HLOOKUP(D13,BASEDATI!$C$4:$H$5,2,FALSE),HLOOKUP(D14,BASEDATI!$C$4:$H$5,2,FALSE),HLOOKUP(D15,BASEDATI!$C$4:$H$5,2,FALSE),HLOOKUP(D16,BASEDATI!$C$4:$H$5,2,FALSE),HLOOKUP(D17,BASEDATI!$C$4:$H$5,2,FALSE))/COUNTA(D12:D17),0) -> 0 | H11: =IFERROR(SUM(HLOOKUP(H12,BASEDATI!$C$4:$H$5,2,FALSE),HLOOKUP(H13,BASEDATI!$C$4:$H$5,2,FALSE),HLOOKUP(H14,BASEDATI!$C$4:$H$5,2,FALSE),HLOOKUP(H15,BASEDATI!$C$4:$H$5,2,FALSE),HLOOKUP(H16,BASEDATI!$C$4:$H$5,2,FALSE),HLOOKUP(H17,BASEDATI!$C$4:$H$5,2,FALSE))/COUNTA(H12:H17),0) -> 65 | I11: =IFERROR(SUM(HLOOKUP(I12,BASEDATI!$C$4:$H$5,2,FALSE),HLOOKUP(I13,BASEDATI!$C$4:$H$5,2,FALSE),HLOOKUP(I14,BASEDATI!$C$4:$H$5,2,FALSE),HLOOKUP(I15,BASEDATI!$C$4:$H$5,2,FALSE),HLOOKUP(I16,BASEDATI!$C$4:$H$5,2,FALSE),HLOOKUP(I17,BASEDATI!$C$4:$H$5,2,FALSE))/COUNTA(I12:I17),0) -> 0 | J11: =IFERROR(SUM(HLOOKUP(J12,BASEDATI!$C$4:$H$5,2,FALSE),HLOOKUP(J13,BASEDATI!$C$4:$H$5,2,FALSE),HLOOKUP(J14,BASEDATI!$C$4:$H$5,2,FALSE),HLOOKUP(J15,BASEDATI!$C$4:$H$5,2,FALSE),HLOOKUP(J16,BASEDATI!$C$4:$H$5,2,FALSE),HLOOKUP(J17,BASEDATI!$C$4:$H$5,2,FALSE))/COUNTA(J12:J17),0) -> 0
A12: Forza | B12: Buono | E12: =SUM(IFERROR(HLOOKUP(B12,BASEDATI!$C$4:$H$5,2,FALSE),0),IFERROR(HLOOKUP(C12,BASEDATI!$C$4:$H$5,2,FALSE),0),IFERROR(HLOOKUP(D12,BASEDATI!$C$4:$H$5,2,FALSE),0))/COUNTA(B12:D12) -> 70 | F12: =LEFT(A12,3) -> For | G12: Tuffo | H12: Sufficiente | K12: =SUM(IFERROR(HLOOKUP(H12,BASEDATI!$C$4:$H$5,2,FALSE),0),IFERROR(HLOOKUP(I12,BASEDATI!$C$4:$H$5,2,FALSE),0),IFERROR(HLOOKUP(J12,BASEDATI!$C$4:$H$5,2,FALSE),0))/COUNTA(H12:J12) -> 60 | L12: =LEFT(G12,3) -> Tuf
A13: Velocità | B13: Sufficiente | E13: =SUM(IFERROR(HLOOKUP(B13,BASEDATI!$C$4:$H$5,2,FALSE),0),IFERROR(HLOOKUP(C13,BASEDATI!$C$4:$H$5,2,FALSE),0),IFERROR(HLOOKUP(D13,BASEDATI!$C$4:$H$5,2,FALSE),0))/COUNTA(B13:D13) -> 60 | F13: =LEFT(A13,3) -> Vel | G13: Spaccata | H13: Sufficiente | K13: =SUM(IFERROR(HLOOKUP(H13,BASEDATI!$C$4:$H$5,2,FALSE),0),IFERROR(HLOOKUP(I13,BASEDATI!$C$4:$H$5,2,FALSE),0),IFERROR(HLOOKUP(J13,BASEDATI!$C$4:$H$5,2,FALSE),0))/COUNTA(H13:J13) -> 60 | L13: =LEFT(G13,3) -> Spa
A14: Resistenza | B14: Buono | E14: =SUM(IFERROR(HLOOKUP(B14,BASEDATI!$C$4:$H$5,2,FALSE),0),IFERROR(HLOOKUP(C14,BASEDATI!$C$4:$H$5,2,FALSE),0),IFERROR(HLOOKUP(D14,BASEDATI!$C$4:$H$5,2,FALSE),0))/COUNTA(B14:D14) -> 70 | F14: =LEFT(A14,3) -> Res | G14: Uscita | H14: Sufficiente | K14: =SUM(IFERROR(HLOOKUP(H14,BASEDATI!$C$4:$H$5,2,FALSE),0),IFERROR(HLOOKUP(I14,BASEDATI!$C$4:$H$5,2,FALSE),0),IFERROR(HLOOKUP(J14,BASEDATI!$C$4:$H$5,2,FALSE),0))/COUNTA(H14:J14) -> 60 | L14: =LEFT(G14,3) -> Usc
A15: Coordinazione | B15: Sufficiente | E15: =SUM(IFERROR(HLOOKUP(B15,BASEDATI!$C$4:$H$5,2,FALSE),0),IFERROR(HLOOKUP(C15,BASEDATI!$C$4:$H$5,2,FALSE),0),IFERROR(HLOOKUP(D15,BASEDATI!$C$4:$H$5,2,FALSE),0))/COUNTA(B15:D15) -> 60 | F15: =LEFT(A15,3) -> Coo | G15: Presa | H15: Buono | K15: =SUM(IFERROR(HLOOKUP(H15,BASEDATI!$C$4:$H$5,2,FALSE),0),IFERROR(HLOOKUP(I15,BASEDATI!$C$4:$H$5,2,FALSE),0),IFERROR(HLOOKUP(J15,BASEDATI!$C$4:$H$5,2,FALSE),0))/COUNTA(H15:J15) -> 70 | L15: =LEFT(G15,3) -> Pre
A16: Rapidità | B16: Sufficiente | E16: =SUM(IFERROR(HLOOKUP(B16,BASEDATI!$C$4:$H$5,2,FALSE),0),IFERROR(HLOOKUP(C16,BASEDATI!$C$4:$H$5,2,FALSE),0),IFERROR(HLOOKUP(D16,BASEDATI!$C$4:$H$5,2,FALSE),0))/COUNTA(B16:D16) -> 60 | F16: =LEFT(A16,3) -> Rap | G16: Rinvio con mani | H16: Buono | K16: =SUM(IFERROR(HLOOKUP(H16,BASEDATI!$C$4:$H$5,2,FALSE),0),IFERROR(HLOOKUP(I16,BASEDATI!$C$4:$H$5,2,FALSE),0),IFERROR(HLOOKUP(J16,BASEDATI!$C$4:$H$5,2,FALSE),0))/COUNTA(H16:J16) -> 70 | L16: =LEFT(G16,3) -> Rin
A17: Recupero | B17: Buono | E17: =SUM(IFERROR(HLOOKUP(B17,BASEDATI!$C$4:$H$5,2,FALSE),0),IFERROR(HLOOKUP(C17,BASEDATI!$C$4:$H$5,2,FALSE),0),IFERROR(HLOOKUP(D17,BASEDATI!$C$4:$H$5,2,FALSE),0))/COUNTA(B17:D17) -> 70 | F17: =LEFT(A17,3) -> Rec | G17: Passagio | H17: Buono | K17: =SUM(IFERROR(HLOOKUP(H17,BASEDATI!$C$4:$H$5,2,FALSE),0),IFERROR(HLOOKUP(I17,BASEDATI!$C$4:$H$5,2,FALSE),0),IFERROR(HLOOKUP(J17,BASEDATI!$C$4:$H$5,2,FALSE),0))/COUNTA(H17:J17) -> 70 | L17: =LEFT(G17,3) -> Pas
A18: VALUTAZIONE TATTICA | B18: =B10 -> 45778 | C18: =C10 -> 45901 | D18: =D10 -> 45992 | E18: MEDIA | G18: VALUTAZIONE PISICOLOGICA | H18: =H10 -> 45778 | I18: =I10 -> 45901 | J18: =J10 -> 45992 | K18: MEDIA
B19: =IFERROR(SUM(HLOOKUP(B20,BASEDATI!$C$4:$H$5,2,FALSE),HLOOKUP(B21,BASEDATI!$C$4:$H$5,2,FALSE),HLOOKUP(B22,BASEDATI!$C$4:$H$5,2,FALSE),HLOOKUP(B23,BASEDATI!$C$4:$H$5,2,FALSE),HLOOKUP(B24,BASEDATI!$C$4:$H$5,2,FALSE),HLOOKUP(B25,BASEDATI!$C$4:$H$5,2,FALSE))/COUNTA(B20:B25),0) -> 65 | C19: =IFERROR(SUM(HLOOKUP(C20,BASEDATI!$C$4:$H$5,2,FALSE),HLOOKUP(C21,BASEDATI!$C$4:$H$5,2,FALSE),HLOOKUP(C22,BASEDATI!$C$4:$H$5,2,FALSE),HLOOKUP(C23,BASEDATI!$C$4:$H$5,2,FALSE),HLOOKUP(C24,BASEDATI!$C$4:$H$5,2,FALSE),HLOOKUP(C25,BASEDATI!$C$4:$H$5,2,FALSE))/COUNTA(C20:C25),0) -> 0 | D19: =IFERROR(SUM(HLOOKUP(D20,BASEDATI!$C$4:$H$5,2,FALSE),HLOOKUP(D21,BASEDATI!$C$4:$H$5,2,FALSE),HLOOKUP(D22,BASEDATI!$C$4:$H$5,2,FALSE),HLOOKUP(D23,BASEDATI!$C$4:$H$5,2,FALSE),HLOOKUP(D24,BASEDATI!$C$4:$H$5,2,FALSE),HLOOKUP(D25,BASEDATI!$C$4:$H$5,2,FALSE))/COUNTA(D20:D25),0) -> 0 | H19: =IFERROR(SUM(HLOOKUP(H20,BASEDATI!$C$4:$H$5,2,FALSE),HLOOKUP(H21,BASEDATI!$C$4:$H$5,2,FALSE),HLOOKUP(H22,BASEDATI!$C$4:$H$5,2,FALSE),HLOOKUP(H23,BASEDATI!$C$4:$H$5,2,FALSE),HLOOKUP(H24,BASEDATI!$C$4:$H$5,2,FALSE),HLOOKUP(H25,BASEDATI!$C$4:$H$5,2,FALSE))/COUNTA(H20:H25),0) -> 66.666667 | I19: =IFERROR(SUM(HLOOKUP(I20,BASEDATI!$C$4:$H$5,2,FALSE),HLOOKUP(I21,BASEDATI!$C$4:$H$5,2,FALSE),HLOOKUP(I22,BASEDATI!$C$4:$H$5,2,FALSE),HLOOKUP(I23,BASEDATI!$C$4:$H$5,2,FALSE),HLOOKUP(I24,BASEDATI!$C$4:$H$5,2,FALSE),HLOOKUP(I25,BASEDATI!$C$4:$H$5,2,FALSE))/COUNTA(I20:I25),0) -> 0 | J19: =IFERROR(SUM(HLOOKUP(J20,BASEDATI!$C$4:$H$5,2,FALSE),HLOOKUP(J21,BASEDATI!$C$4:$H$5,2,FALSE),HLOOKUP(J22,BASEDATI!$C$4:$H$5,2,FALSE),HLOOKUP(J23,BASEDATI!$C$4:$H$5,2,FALSE),HLOOKUP(J24,BASEDATI!$C$4:$H$5,2,FALSE),HLOOKUP(J25,BASEDATI!$C$4:$H$5,2,FALSE))/COUNTA(J20:J25),0) -> 0
A20: Piazzamento | B20: Sufficiente | E20: =SUM(IFERROR(HLOOKUP(B20,BASEDATI!$C$4:$H$5,2,FALSE),0),IFERROR(HLOOKUP(C20,BASEDATI!$C$4:$H$5,2,FALSE),0),IFERROR(HLOOKUP(D20,BASEDATI!$C$4:$H$5,2,FALSE),0))/COUNTA(B20:D20) -> 60 | F20: =LEFT(A20,3) -> Pia | G20: Leadership | H20: Buono | K20: =SUM(IFERROR(HLOOKUP(H20,BASEDATI!$C$4:$H$5,2,FALSE),0),IFERROR(HLOOKUP(I20,BASEDATI!$C$4:$H$5,2,FALSE),0),IFERROR(HLOOKUP(J20,BASEDATI!$C$4:$H$5,2,FALSE),0))/COUNTA(H20:J20) -> 70 | L20: =LEFT(G20,3) -> Lea
A21: Cambio di posizione | B21: Buono | E21: =SUM(IFERROR(HLOOKUP(B21,BASEDATI!$C$4:$H$5,2,FALSE),0),IFERROR(HLOOKUP(C21,BASEDATI!$C$4:$H$5,2,FALSE),0),IFERROR(HLOOKUP(D21,BASEDATI!$C$4:$H$5,2,FALSE),0))/COUNTA(B21:D21) -> 70 | F21: =LEFT(A21,3) -> Cam | G21: Apprendimento | H21: Buono | K21: =SUM(IFERROR(HLOOKUP(H21,BASEDATI!$C$4:$H$5,2,FALSE),0),IFERROR(HLOOKUP(I21,BASEDATI!$C$4:$H$5,2,FALSE),0),IFERROR(HLOOKUP(J21,BASEDATI!$C$4:$H$5,2,FALSE),0))/COUNTA(H21:J21) -> 70 | L21: =LEFT(G21,3) -> App
A22: Difesa della porta | B22: Sufficiente | E22: =SUM(IFERROR(HLOOKUP(B22,BASEDATI!$C$4:$H$5,2,FALSE),0),IFERROR(HLOOKUP(C22,BASEDATI!$C$4:$H$5,2,FALSE),0),IFERROR(HLOOKUP(D22,BASEDATI!$C$4:$H$5,2,FALSE),0))/COUNTA(B22:D22) -> 60 | F22: =LEFT(A22,3) -> Dif | G22: Impegno | H22: Buono | K22: =SUM(IFERROR(HLOOKUP(H22,BASEDATI!$C$4:$H$5,2,FALSE),0),IFERROR(HLOOKUP(I22,BASEDATI!$C$4:$H$5,2,FALSE),0),IFERROR(HLOOKUP(J22,BASEDATI!$C$4:$H$5,2,FALSE),0))/COUNTA(H22:J22) -> 70 | L22: =LEFT(G22,3) -> Imp
A23: Guida della difesa | B23: Buono | E23: =SUM(IFERROR(HLOOKUP(B23,BASEDATI!$C$4:$H$5,2,FALSE),0),IFERROR(HLOOKUP(C23,BASEDATI!$C$4:$H$5,2,FALSE),0),IFERROR(HLOOKUP(D23,BASEDATI!$C$4:$H$5,2,FALSE),0))/COUNTA(B23:D23) -> 70 | F23: =LEFT(A23,3) -> Gui | G23: Resilienza | H23: Buono | K23: =SUM(IFERROR(HLOOKUP(H23,BASEDATI!$C$4:$H$5,2,FALSE),0),IFERROR(HLOOKUP(I23,BASEDATI!$C$4:$H$5,2,FALSE),0),IFERROR(HLOOKUP(J23,BASEDATI!$C$4:$H$5,2,FALSE),0))/COUNTA(H23:J23) -> 70 | L23: =LEFT(G23,3) -> Res
A24: Lettura situazione | B24: Sufficiente | E24: =SUM(IFERROR(HLOOKUP(B24,BASEDATI!$C$4:$H$5,2,FALSE),0),IFERROR(HLOOKUP(C24,BASEDATI!$C$4:$H$5,2,FALSE),0),IFERROR(HLOOKUP(D24,BASEDATI!$C$4:$H$5,2,FALSE),0))/COUNTA(B24:D24) -> 60 | F24: =LEFT(A24,3) -> Let | G24: Emotività | H24: Sufficiente | K24: =SUM(IFERROR(HLOOKUP(H24,BASEDATI!$C$4:$H$5,2,FALSE),0),IFERROR(HLOOKUP(I24,BASEDATI!$C$4:$H$5,2,FALSE),0),IFERROR(HLOOKUP(J24,BASEDATI!$C$4:$H$5,2,FALSE),0))/COUNTA(H24:J24) -> 60 | L24: =LEFT(G24,3) -> Emo
A25: Transizione | B25: Buono | E25: =SUM(IFERROR(HLOOKUP(B25,BASEDATI!$C$4:$H$5,2,FALSE),0),IFERROR(HLOOKUP(C25,BASEDATI!$C$4:$H$5,2,FALSE),0),IFERROR(HLOOKUP(D25,BASEDATI!$C$4:$H$5,2,FALSE),0))/COUNTA(B25:D25) -> 70 | F25: =LEFT(A25,3) -> Tra | G25: Rispetto | H25: Sufficiente | K25: =SUM(IFERROR(HLOOKUP(H25,BASEDATI!$C$4:$H$5,2,FALSE),0),IFERROR(HLOOKUP(I25,BASEDATI!$C$4:$H$5,2,FALSE),0),IFERROR(HLOOKUP(J25,BASEDATI!$C$4:$H$5,2,FALSE),0))/COUNTA(H25:J25) -> 60 | L25: =LEFT(G25,3) -> Ris
A26: SCHEDA DI VALUTAZIONE PERFORMANCE
A27: =A2 -> LOFFREDA Giammaria | E27: D.NASCITA | F27: STAGIONE | G27: VALUTAZIONE GENERALE | H27: =B30 -> 45778 | I27: =C33 -> 45901 | J27: =D33 -> 45992 | K27: MEDIA
E28: =E3 -> 41217 | F28: =F3 -> 2025/2026 | H28: =IFERROR(AVERAGE(H29:H34),0) -> 63.571627 | I28: =IFERROR(AVERAGE(I29:I34),0) -> 0 | J28: =IFERROR(AVERAGE(J29:J34),0) -> 0
B29: PESO (kg) | E29: PIEDE FORTE | F29: PIEDE DEBOLE | G29: FISICA | H29: =B36 -> 68.333333 | I29: =C36 -> 0 | J29: =D36 -> 0 | K29: =IFERROR(AVERAGEIF(H29:J29,">0"),0) -> 68.333333 | L29: FIS
B30: =B5 -> 45778 | C30: =C5 -> 45901 | D30: =D5 -> 45992 | E30: Dx | F30: Sufficiente | G30: TATTICA | H30: =B44 -> 60 | I30: =C44 -> 0 | J30: =D44 -> 0 | K30: =IFERROR(AVERAGEIF(H30:J30,">0"),0) -> 60 | L30: TAT
B31: =B6 -> 45 | E31: RUOLO | F31: ATTITUDINE | G31: TECNICA | H31: =H36 -> 68.333333 | I31: =I36 -> 0 | J31: =J36 -> 0 | K31: =IFERROR(AVERAGEIF(H31:J31,">0"),0) -> 68.333333 | L31: TEC
B32: ALTEZZA (cm) | E32: Portiere | F32: Portiere | G32: PSICOLOGIA | H32: =H44 -> 65 | I32: =I44 -> 0 | J32: =J44 -> 0 | K32: =IFERROR(AVERAGEIF(H32:J32,">0"),0) -> 65 | L32: PSI
B33: =B30 -> 45778 | C33: =C30 -> 45901 | D33: =D30 -> 45992 | E33: BMI | F33: MORFOLOGIA | G33: BMIx3 | H33: =IF(IFERROR(B31/(B34/100*B34/100),0)*3>70,120-IFERROR(B31/(B34/100*B34/100),0)*3,IFERROR(B31/(B34/100*B34/100),0)*3) -> 56.191467 | I33: =IF(IFERROR(C31/(C34/100*C34/100),0)*3>70,120-IFERROR(C31/(C34/100*C34/100),0)*3,IFERROR(C31/(C34/100*C34/100),0)*3) -> 0 | J33: =IF(IFERROR(D31/(D34/100*D34/100),0)*3>70,120-IFERROR(D31/(D34/100*D34/100),0)*3,IFERROR(D31/(D34/100*D34/100),0)*3) -> 0 | K33: =IFERROR(AVERAGEIF(H33:J33,">0"),0) -> 56.191467 | L33: =LEFT(G33,3) -> BMI
B34: 155 | C34: 156 | E34: =E9 -> Sottopeso | F34: Brevilineo
A35: VALUTAZIONE FISICA | B35: =B33 -> 45778 | C35: =C33 -> 45901 | D35: =D33 -> 45992 | E35: MEDIA | G35: VALUTAZIONE TECNICA | H35: =H27 -> 45778 | I35: =I27 -> 45901 | J35: =J27 -> 45992 | K35: MEDIA
B36: =IFERROR(SUM(HLOOKUP(B37,BASEDATI!$C$4:$H$5,2,FALSE),HLOOKUP(B38,BASEDATI!$C$4:$H$5,2,FALSE),HLOOKUP(B39,BASEDATI!$C$4:$H$5,2,FALSE),HLOOKUP(B40,BASEDATI!$C$4:$H$5,2,FALSE),HLOOKUP(B41,BASEDATI!$C$4:$H$5,2,FALSE),HLOOKUP(B42,BASEDATI!$C$4:$H$5,2,FALSE))/COUNTA(B37:B42),0) -> 68.333333 | C36: =IFERROR(SUM(HLOOKUP(C37,BASEDATI!$C$4:$H$5,2,FALSE),HLOOKUP(C38,BASEDATI!$C$4:$H$5,2,FALSE),HLOOKUP(C39,BASEDATI!$C$4:$H$5,2,FALSE),HLOOKUP(C40,BASEDATI!$C$4:$H$5,2,FALSE),HLOOKUP(C41,BASEDATI!$C$4:$H$5,2,FALSE),HLOOKUP(C42,BASEDATI!$C$4:$H$5,2,FALSE))/COUNTA(C37:C42),0) -> 0 | D36: =IFERROR(SUM(HLOOKUP(D37,BASEDATI!$C$4:$H$5,2,FALSE),HLOOKUP(D38,BASEDATI!$C$4:$H$5,2,FALSE),HLOOKUP(D39,BASEDATI!$C$4:$H$5,2,FALSE),HLOOKUP(D40,BASEDATI!$C$4:$H$5,2,FALSE),HLOOKUP(D41,BASEDATI!$C$4:$H$5,2,FALSE),HLOOKUP(D42,BASEDATI!$C$4:$H$5,2,FALSE))/COUNTA(D37:D42),0) -> 0 | H36: =IFERROR(SUM(HLOOKUP(H37,BASEDATI!$C$4:$H$5,2,FALSE),HLOOKUP(H38,BASEDATI!$C$4:$H$5,2,FALSE),HLOOKUP(H39,BASEDATI!$C$4:$H$5,2,FALSE),HLOOKUP(H40,BASEDATI!$C$4:$H$5,2,FALSE),HLOOKUP(H41,BASEDATI!$C$4:$H$5,2,FALSE),HLOOKUP(H42,BASEDATI!$C$4:$H$5,2,FALSE))/COUNTA(H37:H42),0) -> 68.333333 | I36: =IFERROR(SUM(HLOOKUP(I37,BASEDATI!$C$4:$H$5,2,FALSE),HLOOKUP(I38,BASEDATI!$C$4:$H$5,2,FALSE),HLOOKUP(I39,BASEDATI!$C$4:$H$5,2,FALSE),HLOOKUP(I40,BASEDATI!$C$4:$H$5,2,FALSE),HLOOKUP(I41,BASEDATI!$C$4:$H$5,2,FALSE),HLOOKUP(I42,BASEDATI!$C$4:$H$5,2,FALSE))/COUNTA(I37:I42),0) -> 0 | J36: =IFERROR(SUM(HLOOKUP(J37,BASEDATI!$C$4:$H$5,2,FALSE),HLOOKUP(J38,BASEDATI!$C$4:$H$5,2,FALSE),HLOOKUP(J39,BASEDATI!$C$4:$H$5,2,FALSE),HLOOKUP(J40,BASEDATI!$C$4:$H$5,2,FALSE),HLOOKUP(J41,BASEDATI!$C$4:$H$5,2,FALSE),HLOOKUP(J42,BASEDATI!$C$4:$H$5,2,FALSE))/COUNTA(J37:J42),0) -> 0
A37: Forza | B37: Buono | E37: =SUM(IFERROR(HLOOKUP(B37,BASEDATI!$C$4:$H$5,2,FALSE),0),IFERROR(HLOOKUP(C37,BASEDATI!$C$4:$H$5,2,FALSE),0),IFERROR(HLOOKUP(D37,BASEDATI!$C$4:$H$5,2,FALSE),0))/COUNTA(B37:D37) -> 70 | F37: =LEFT(A37,3) -> For | G37: Tuffo | H37: Buono | K37: =SUM(IFERROR(HLOOKUP(H37,BASEDATI!$C$4:$H$5,2,FALSE),0),IFERROR(HLOOKUP(I37,BASEDATI!$C$4:$H$5,2,FALSE),0),IFERROR(HLOOKUP(J37,BASEDATI!$C$4:$H$5,2,FALSE),0))/COUNTA(H37:J37) -> 70 | L37: =LEFT(G37,3) -> Tuf
A38: Velocità | B38: Buono | E38: =SUM(IFERROR(HLOOKUP(B38,BASEDATI!$C$4:$H$5,2,FALSE),0),IFERROR(HLOOKUP(C38,BASEDATI!$C$4:$H$5,2,FALSE),0),IFERROR(HLOOKUP(D38,BASEDATI!$C$4:$H$5,2,FALSE),0))/COUNTA(B38:D38) -> 70 | F38: =LEFT(A38,3) -> Vel | G38: Spaccata | H38: Buono | K38: =SUM(IFERROR(HLOOKUP(H38,BASEDATI!$C$4:$H$5,2,FALSE),0),IFERROR(HLOOKUP(I38,BASEDATI!$C$4:$H$5,2,FALSE),0),IFERROR(HLOOKUP(J38,BASEDATI!$C$4:$H$5,2,FALSE),0))/COUNTA(H38:J38) -> 70 | L38: =LEFT(G38,3) -> Spa
A39: Resistenza | B39: Buono | E39: =SUM(IFERROR(HLOOKUP(B39,BASEDATI!$C$4:$H$5,2,FALSE),0),IFERROR(HLOOKUP(C39,BASEDATI!$C$4:$H$5,2,FALSE),0),IFERROR(HLOOKUP(D39,BASEDATI!$C$4:$H$5,2,FALSE),0))/COUNTA(B39:D39) -> 70 | F39: =LEFT(A39,3) -> Res | G39: Uscita | H39: Buono | K39: =SUM(IFERROR(HLOOKUP(H39,BASEDATI!$C$4:$H$5,2,FALSE),0),IFERROR(HLOOKUP(I39,BASEDATI!$C$4:$H$5,2,FALSE),0),IFERROR(HLOOKUP(J39,BASEDATI!$C$4:$H$5,2,FALSE),0))/COUNTA(H39:J39) -> 70 | L39: =LEFT(G39,3) -> Usc
A40: Coordinazione | B40: Sufficiente | E40: =SUM(IFERROR(HLOOKUP(B40,BASEDATI!$C$4:$H$5,2,FALSE),0),IFERROR(HLOOKUP(C40,BASEDATI!$C$4:$H$5,2,FALSE),0),IFERROR(HLOOKUP(D40,BASEDATI!$C$4:$H$5,2,FALSE),0))/COUNTA(B40:D40) -> 60 | F40: =LEFT(A40,3) -> Coo | G40: Presa | H40: Sufficiente | K40: =SUM(IFERROR(HLOOKUP(H40,BASEDATI!$C$4:$H$5,2,FALSE),0),IFERROR(HLOOKUP(I40,BASEDATI!$C$4:$H$5,2,FALSE),0),IFERROR(HLOOKUP(J40,BASEDATI!$C$4:$H$5,2,FALSE),0))/COUNTA(H40:J40) -> 60 | L40: =LEFT(G40,3) -> Pre
...

Sheet FADIL Youssef
A1: SCHEDA DI AUTOVALUTAZIONE PERFORMANCE
A2: FADIL YOUSSEF | E2: D.NASCITA | F2: STAGIONE | G2: VALUTAZIONE GENERALE | H2: =B5 -> 45778 | I2: =C8 -> 45901 | J2: =D8 -> 45992 | K2: MEDIA
E3: 41217 | F3: 2025/2026 | H3: =IFERROR(AVERAGE(H4:H9),0) -> 61.908562 | I3: =IFERROR(AVERAGE(I4:I9),0) -> 0 | J3: =IFERROR(AVERAGE(J4:J9),0) -> 0
A4: #VALUE! | B4: PESO (kg) | E4: PIEDE FORTE | F4: PIEDE DEBOLE | G4: FISICA | H4: =B11 -> 60 | I4: =C11 -> 0 | J4: =D11 -> 0 | K4: =IFERROR(AVERAGEIF(H4:J4,">0"),0) -> 60 | L4: =LEFT(G4,3) -> FIS
B5: 45778 | C5: 45901 | D5: 45992 | E5: Dx | F5: Sufficiente | G5: TATTICA | H5: =B19 -> 65 | I5: =C19 -> 0 | J5: =D19 -> 0 | K5: =IFERROR(AVERAGEIF(H5:J5,">0"),0) -> 65 | L5: =LEFT(G5,3) -> TAT
B6: 44 | E6: RUOLO | F6: ATTITUDINE | G6: TECNICA | H6: =H11 -> 66.666667 | I6: =I11 -> 0 | J6: =J11 -> 0 | K6: =IFERROR(AVERAGEIF(H6:J6,">0"),0) -> 66.666667 | L6: =LEFT(G6,3) -> TEC
B7: ALTEZZA (cm) | E7: Difensore | F7: Attacco | G7: PSICOLOGIA | H7: =H19 -> 65 | I7: =I19 -> 0 | J7: =J19 -> 0 | K7: =IFERROR(AVERAGEIF(H7:J7,">0"),0) -> 65 | L7: =LEFT(G7,3) -> PSI
B8: =B5 -> 45778 | C8: =C5 -> 45901 | D8: =D5 -> 45992 | E8: BMI | F8: MORFOLOGIA | G8: BMIx3 | H8: =IFERROR(B6/(B9/100*B9/100),0)*3 -> 52.876142 | I8: =IFERROR(C6/(C9/100*C9/100),0)*3 -> 0 | J8: =IFERROR(D6/(D9/100*D9/100),0)*3 -> 0 | K8: =IFERROR(ROUND(AVERAGEIF(H8:J8,">0"),0),0) -> 53 | L8: BMI
B9: 158 | E9: =_xlfn.XLOOKUP(K8/3,BASEDATI!B15:B21,BASEDATI!C15:C21,,1) -> Sottopeso | F9: Normolineo
A10: VALUTAZIONE FISICA | B10: =B8 -> 45778 | C10: =C8 -> 45901 | D10: =D8 -> 45992 | E10: MEDIA | G10: VALUTAZIONE TECNICA | H10: =H2 -> 45778 | I10: =I2 -> 45901 | J10: =J2 -> 45992 | K10: MEDIA
B11: =IFERROR(SUM(HLOOKUP(B12,BASEDATI!$C$4:$H$5,2,FALSE),HLOOKUP(B13,BASEDATI!$C$4:$H$5,2,FALSE),HLOOKUP(B14,BASEDATI!$C$4:$H$5,2,FALSE),HLOOKUP(B15,BASEDATI!$C$4:$H$5,2,FALSE),HLOOKUP(B16,BASEDATI!$C$4:$H$5,2,FALSE),HLOOKUP(B17,BASEDATI!$C$4:$H$5,2,FALSE))/COUNTA(B12:B17),0) -> 60 | C11: =IFERROR(SUM(HLOOKUP(C12,BASEDATI!$C$4:$H$5,2,FALSE),HLOOKUP(C13,BASEDATI!$C$4:$H$5,2,FALSE),HLOOKUP(C14,BASEDATI!$C$4:$H$5,2,FALSE),HLOOKUP(C15,BASEDATI!$C$4:$H$5,2,FALSE),HLOOKUP(C16,BASEDATI!$C$4:$H$5,2,FALSE),HLOOKUP(C17,BASEDATI!$C$4:$H$5,2,FALSE))/COUNTA(C12:C17),0) -> 0 | D11: =IFERROR(SUM(HLOOKUP(D12,BASEDATI!$C$4:$H$5,2,FALSE),HLOOKUP(D13,BASEDATI!$C$4:$H$5,2,FALSE),HLOOKUP(D14,BASEDATI!$C$4:$H$5,2,FALSE),HLOOKUP(D15,BASEDATI!$C$4:$H$5,2,FALSE),HLOOKUP(D16,BASEDATI!$C$4:$H$5,2,FALSE),HLOOKUP(D17,BASEDATI!$C$4:$H$5,2,FALSE))/COUNTA(D12:D17),0) -> 0 | H11: =IFERROR(SUM(HLOOKUP(H12,BASEDATI!$C$4:$H$5,2,FALSE),HLOOKUP(H13,BASEDATI!$C$4:$H$5,2,FALSE),HLOOKUP(H14,BASEDATI!$C$4:$H$5,2,FALSE),HLOOKUP(H15,BASEDATI!$C$4:$H$5,2,FALSE),HLOOKUP(H16,BASEDATI!$C$4:$H$5,2,FALSE),HLOOKUP(H17,BASEDATI!$C$4:$H$5,2,FALSE))/COUNTA(H12:H17),0) -> 66.666667 | I11: =IFERROR(SUM(HLOOKUP(I12,BASEDATI!$C$4:$H$5,2,FALSE),HLOOKUP(I13,BASEDATI!$C$4:$H$5,2,FALSE),HLOOKUP(I14,BASEDATI!$C$4:$H$5,2,FALSE),HLOOKUP(I15,BASEDATI!$C$4:$H$5,2,FALSE),HLOOKUP(I16,BASEDATI!$C$4:$H$5,2,FALSE),HLOOKUP(I17,BASEDATI!$C$4:$H$5,2,FALSE))/COUNTA(I12:I17),0) -> 0 | J11: =IFERROR(SUM(HLOOKUP(J12,BASEDATI!$C$4:$H$5,2,FALSE),HLOOKUP(J13,BASEDATI!$C$4:$H$5,2,FALSE),HLOOKUP(J14,BASEDATI!$C$4:$H$5,2,FALSE),HLOOKUP(J15,BASEDATI!$C$4:$H$5,2,FALSE),HLOOKUP(J16,BASEDATI!$C$4:$H$5,2,FALSE),HLOOKUP(J17,BASEDATI!$C$4:$H$5,2,FALSE))/COUNTA(J12:J17),0) -> 0
A12: Forza | B12: Sufficiente | E12: =SUM(IFERROR(HLOOKUP(B12,BASEDATI!$C$4:$H$5,2,FALSE),0),IFERROR(HLOOKUP(C12,BASEDATI!$C$4:$H$5,2,FALSE),0),IFERROR(HLOOKUP(D12,BASEDATI!$C$4:$H$5,2,FALSE),0))/COUNTA(B12:D12) -> 60 | F12: =LEFT(A12,3) -> For | G12: Guida e difesa palla | H12: Sufficiente | K12: =SUM(IFERROR(HLOOKUP(H12,BASEDATI!$C$4:$H$5,2,FALSE),0),IFERROR(HLOOKUP(I12,BASEDATI!$C$4:$H$5,2,FALSE),0),IFERROR(HLOOKUP(J12,BASEDATI!$C$4:$H$5,2,FALSE),0))/COUNTA(H12:J12) -> 60 | L12: =LEFT(G12,3) -> Gui
A13: Velocità | B13: Sufficiente | E13: =SUM(IFERROR(HLOOKUP(B13,BASEDATI!$C$4:$H$5,2,FALSE),0),IFERROR(HLOOKUP(C13,BASEDATI!$C$4:$H$5,2,FALSE),0),IFERROR(HLOOKUP(D13,BASEDATI!$C$4:$H$5,2,FALSE),0))/COUNTA(B13:D13) -> 60 | F13: =LEFT(A13,3) -> Vel | G13: Contrasto | H13: Buono | K13: =SUM(IFERROR(HLOOKUP(H13,BASEDATI!$C$4:$H$5,2,FALSE),0),IFERROR(HLOOKUP(I13,BASEDATI!$C$4:$H$5,2,FALSE),0),IFERROR(HLOOKUP(J13,BASEDATI!$C$4:$H$5,2,FALSE),0))/COUNTA(H13:J13) -> 70 | L13: =LEFT(G13,3) -> Con
A14: Resistenza | B14: Insufficiente | E14: =SUM(IFERROR(HLOOKUP(B14,BASEDATI!$C$4:$H$5,2,FALSE),0),IFERROR(HLOOKUP(C14,BASEDATI!$C$4:$H$5,2,FALSE),0),IFERROR(HLOOKUP(D14,BASEDATI!$C$4:$H$5,2,FALSE),0))/COUNTA(B14:D14) -> 50 | F14: =LEFT(A14,3) -> Res | G14: Controllo orientato | H14: Sufficiente | K14: =SUM(IFERROR(HLOOKUP(H14,BASEDATI!$C$4:$H$5,2,FALSE),0),IFERROR(HLOOKUP(I14,BASEDATI!$C$4:$H$5,2,FALSE),0),IFERROR(HLOOKUP(J14,BASEDATI!$C$4:$H$5,2,FALSE),0))/COUNTA(H14:J14) -> 60 | L14: =LEFT(G14,3) -> Con
A15: Coordinazione | B15: Buono | E15: =SUM(IFERROR(HLOOKUP(B15,BASEDATI!$C$4:$H$5,2,FALSE),0),IFERROR(HLOOKUP(C15,BASEDATI!$C$4:$H$5,2,FALSE),0),IFERROR(HLOOKUP(D15,BASEDATI!$C$4:$H$5,2,FALSE),0))/COUNTA(B15:D15) -> 70 | F15: =LEFT(A15,3) -> Coo | G15: Tiro in porta | H15: Ottimo | K15: =SUM(IFERROR(HLOOKUP(H15,BASEDATI!$C$4:$H$5,2,FALSE),0),IFERROR(HLOOKUP(I15,BASEDATI!$C$4:$H$5,2,FALSE),0),IFERROR(HLOOKUP(J15,BASEDATI!$C$4:$H$5,2,FALSE),0))/COUNTA(H15:J15) -> 80 | L15: =LEFT(G15,3) -> Tir
A16: Rapidità | B16: Sufficiente | E16: =SUM(IFERROR(HLOOKUP(B16,BASEDATI!$C$4:$H$5,2,FALSE),0),IFERROR(HLOOKUP(C16,BASEDATI!$C$4:$H$5,2,FALSE),0),IFERROR(HLOOKUP(D16,BASEDATI!$C$4:$H$5,2,FALSE),0))/COUNTA(B16:D16) -> 60 | F16: =LEFT(A16,3) -> Rap | G16: Uno contro uno | H16: Sufficiente | K16: =SUM(IFERROR(HLOOKUP(H16,BASEDATI!$C$4:$H$5,2,FALSE),0),IFERROR(HLOOKUP(I16,BASEDATI!$C$4:$H$5,2,FALSE),0),IFERROR(HLOOKUP(J16,BASEDATI!$C$4:$H$5,2,FALSE),0))/COUNTA(H16:J16) -> 60 | L16: =LEFT(G16,3) -> Uno
A17: Recupero | B17: Sufficiente | E17: =SUM(IFERROR(HLOOKUP(B17,BASEDATI!$C$4:$H$5,2,FALSE),0),IFERROR(HLOOKUP(C17,BASEDATI!$C$4:$H$5,2,FALSE),0),IFERROR(HLOOKUP(D17,BASEDATI!$C$4:$H$5,2,FALSE),0))/COUNTA(B17:D17) -> 60 | F17: =LEFT(A17,3) -> Rec | G17: Uso piede debole | H17: Buono | K17: =SUM(IFERROR(HLOOKUP(H17,BASEDATI!$C$4:$H$5,2,FALSE),0),IFERROR(HLOOKUP(I17,BASEDATI!$C$4:$H$5,2,FALSE),0),IFERROR(HLOOKUP(J17,BASEDATI!$C$4:$H$5,2,FALSE),0))/COUNTA(H17:J17) -> 70 | L17: =LEFT(G17,3) -> Uso
A18: VALUTAZIONE TATTICA | B18: =B10 -> 45778 | C18: =C10 -> 45901 | D18: =D10 -> 45992 | E18: MEDIA | G18: VALUTAZIONE PISICOLOGICA | H18: =H10 -> 45778 | I18: =I10 -> 45901 | J18: =J10 -> 45992 | K18: MEDIA
B19: =IFERROR(SUM(HLOOKUP(B20,BASEDATI!$C$4:$H$5,2,FALSE),HLOOKUP(B21,BASEDATI!$C$4:$H$5,2,FALSE),HLOOKUP(B22,BASEDATI!$C$4:$H$5,2,FALSE),HLOOKUP(B23,BASEDATI!$C$4:$H$5,2,FALSE),HLOOKUP(B24,BASEDATI!$C$4:$H$5,2,FALSE),HLOOKUP(B25,BASEDATI!$C$4:$H$5,2,FALSE))/COUNTA(B20:B25),0) -> 65 | C19: =IFERROR(SUM(HLOOKUP(C20,BASEDATI!$C$4:$H$5,2,FALSE),HLOOKUP(C21,BASEDATI!$C$4:$H$5,2,FALSE),HLOOKUP(C22,BASEDATI!$C$4:$H$5,2,FALSE),HLOOKUP(C23,BASEDATI!$C$4:$H$5,2,FALSE),HLOOKUP(C24,BASEDATI!$C$4:$H$5,2,FALSE),HLOOKUP(C25,BASEDATI!$C$4:$H$5,2,FALSE))/COUNTA(C20:C25),0) -> 0 | D19: =IFERROR(SUM(HLOOKUP(D20,BASEDATI!$C$4:$H$5,2,FALSE),HLOOKUP(D21,BASEDATI!$C$4:$H$5,2,FALSE),HLOOKUP(D22,BASEDATI!$C$4:$H$5,2,FALSE),HLOOKUP(D23,BASEDATI!$C$4:$H$5,2,FALSE),HLOOKUP(D24,BASEDATI!$C$4:$H$5,2,FALSE),HLOOKUP(D25,BASEDATI!$C$4:$H$5,2,FALSE))/COUNTA(D20:D25),0) -> 0 | H19: =IFERROR(SUM(HLOOKUP(H20,BASEDATI!$C$4:$H$5,2,FALSE),HLOOKUP(H21,BASEDATI!$C$4:$H$5,2,FALSE),HLOOKUP(H22,BASEDATI!$C$4:$H$5,2,FALSE),HLOOKUP(H23,BASEDATI!$C$4:$H$5,2,FALSE),HLOOKUP(H24,BASEDATI!$C$4:$H$5,2,FALSE),HLOOKUP(H25,BASEDATI!$C$4:$H$5,2,FALSE))/COUNTA(H20:H25),0) -> 65 | I19: =IFERROR(SUM(HLOOKUP(I20,BASEDATI!$C$4:$H$5,2,FALSE),HLOOKUP(I21,BASEDATI!$C$4:$H$5,2,FALSE),HLOOKUP(I22,BASEDATI!$C$4:$H$5,2,FALSE),HLOOKUP(I23,BASEDATI!$C$4:$H$5,2,FALSE),HLOOKUP(I24,BASEDATI!$C$4:$H$5,2,FALSE),HLOOKUP(I25,BASEDATI!$C$4:$H$5,2,FALSE))/COUNTA(I20:I25),0) -> 0 | J19: =IFERROR(SUM(HLOOKUP(J20,BASEDATI!$C$4:$H$5,2,FALSE),HLOOKUP(J21,BASEDATI!$C$4:$H$5,2,FALSE),HLOOKUP(J22,BASEDATI!$C$4:$H$5,2,FALSE),HLOOKUP(J23,BASEDATI!$C$4:$H$5,2,FALSE),HLOOKUP(J24,BASEDATI!$C$4:$H$5,2,FALSE),HLOOKUP(J25,BASEDATI!$C$4:$H$5,2,FALSE))/COUNTA(J20:J25),0) -> 0
A20: Posizionamento | B20: Buono | E20: =SUM(IFERROR(HLOOKUP(B20,BASEDATI!$C$4:$H$5,2,FALSE),0),IFERROR(HLOOKUP(C20,BASEDATI!$C$4:$H$5,2,FALSE),0),IFERROR(HLOOKUP(D20,BASEDATI!$C$4:$H$5,2,FALSE),0))/COUNTA(B20:D20) -> 70 | F20: =LEFT(A20,3) -> Pos | G20: Leadership | H20: Sufficiente | K20: =SUM(IFERROR(HLOOKUP(H20,BASEDATI!$C$4:$H$5,2,FALSE),0),IFERROR(HLOOKUP(I20,BASEDATI!$C$4:$H$5,2,FALSE),0),IFERROR(HLOOKUP(J20,BASEDATI!$C$4:$H$5,2,FALSE),0))/COUNTA(H20:J20) -> 60 | L20: =LEFT(G20,3) -> Lea
A21: Marcamento | B21: Sufficiente | E21: =SUM(IFERROR(HLOOKUP(B21,BASEDATI!$C$4:$H$5,2,FALSE),0),IFERROR(HLOOKUP(C21,BASEDATI!$C$4:$H$5,2,FALSE),0),IFERROR(HLOOKUP(D21,BASEDATI!$C$4:$H$5,2,FALSE),0))/COUNTA(B21:D21) -> 60 | F21: =LEFT(A21,3) -> Mar | G21: Apprendimento | H21: Buono | K21: =SUM(IFERROR(HLOOKUP(H21,BASEDATI!$C$4:$H$5,2,FALSE),0),IFERROR(HLOOKUP(I21,BASEDATI!$C$4:$H$5,2,FALSE),0),IFERROR(HLOOKUP(J21,BASEDATI!$C$4:$H$5,2,FALSE),0))/COUNTA(H21:J21) -> 70 | L21: =LEFT(G21,3) -> App
A22: Smarcamento | B22: Sufficiente | E22: =SUM(IFERROR(HLOOKUP(B22,BASEDATI!$C$4:$H$5,2,FALSE),0),IFERROR(HLOOKUP(C22,BASEDATI!$C$4:$H$5,2,FALSE),0),IFERROR(HLOOKUP(D22,BASEDATI!$C$4:$H$5,2,FALSE),0))/COUNTA(B22:D22) -> 60 | F22: =LEFT(A22,3) -> Sma | G22: Impegno | H22: Buono | K22: =SUM(IFERROR(HLOOKUP(H22,BASEDATI!$C$4:$H$5,2,FALSE),0),IFERROR(HLOOKUP(I22,BASEDATI!$C$4:$H$5,2,FALSE),0),IFERROR(HLOOKUP(J22,BASEDATI!$C$4:$H$5,2,FALSE),0))/COUNTA(H22:J22) -> 70 | L22: =LEFT(G22,3) -> Imp
A23: Visione | B23: Ottimo | E23: =SUM(IFERROR(HLOOKUP(B23,BASEDATI!$C$4:$H$5,2,FALSE),0),IFERROR(HLOOKUP(C23,BASEDATI!$C$4:$H$5,2,FALSE),0),IFERROR(HLOOKUP(D23,BASEDATI!$C$4:$H$5,2,FALSE),0))/COUNTA(B23:D23) -> 80 | F23: =LEFT(A23,3) -> Vis | G23: Resilienza | H23: Sufficiente | K23: =SUM(IFERROR(HLOOKUP(H23,BASEDATI!$C$4:$H$5,2,FALSE),0),IFERROR(HLOOKUP(I23,BASEDATI!$C$4:$H$5,2,FALSE),0),IFERROR(HLOOKUP(J23,BASEDATI!$C$4:$H$5,2,FALSE),0))/COUNTA(H23:J23) -> 60 | L23: =LEFT(G23,3) -> Res
A24: Inserimento | B24: Sufficiente | E24: =SUM(IFERROR(HLOOKUP(B24,BASEDATI!$C$4:$H$5,2,FALSE),0),IFERROR(HLOOKUP(C24,BASEDATI!$C$4:$H$5,2,FALSE),0),IFERROR(HLOOKUP(D24,BASEDATI!$C$4:$H$5,2,FALSE),0))/COUNTA(B24:D24) -> 60 | F24: =LEFT(A24,3) -> Ins | G24: Emotività | H24: Buono | K24: =SUM(IFERROR(HLOOKUP(H24,BASEDATI!$C$4:$H$5,2,FALSE),0),IFERROR(HLOOKUP(I24,BASEDATI!$C$4:$H$5,2,FALSE),0),IFERROR(HLOOKUP(J24,BASEDATI!$C$4:$H$5,2,FALSE),0))/COUNTA(H24:J24) -> 70 | L24: =LEFT(G24,3) -> Emo
A25: Chiusure | B25: Sufficiente | E25: =SUM(IFERROR(HLOOKUP(B25,BASEDATI!$C$4:$H$5,2,FALSE),0),IFERROR(HLOOKUP(C25,BASEDATI!$C$4:$H$5,2,FALSE),0),IFERROR(HLOOKUP(D25,BASEDATI!$C$4:$H$5,2,FALSE),0))/COUNTA(B25:D25) -> 60 | F25: =LEFT(A25,3) -> Chi | G25: Rispetto | H25: Sufficiente | K25: =SUM(IFERROR(HLOOKUP(H25,BASEDATI!$C$4:$H$5,2,FALSE),0),IFERROR(HLOOKUP(I25,BASEDATI!$C$4:$H$5,2,FALSE),0),IFERROR(HLOOKUP(J25,BASEDATI!$C$4:$H$5,2,FALSE),0))/COUNTA(H25:J25) -> 60 | L25: =LEFT(G25,3) -> Ris
A26: SCHEDA DI VALUTAZIONE PERFORMANCE
A27: =A2 -> FADIL YOUSSEF | E27: D.NASCITA | F27: STAGIONE | G27: VALUTAZIONE GENERALE | H27: =B30 -> 45778 | I27: =C33 -> 45901 | J27: =D33 -> 45992 | K27: MEDIA
E28: =E3 -> 41217 | F28: =F3 -> 2025/2026 | H28: =IFERROR(AVERAGE(H29:H34),0) -> 72.277778 | I28: =IFERROR(AVERAGE(I29:I34),0) -> 0 | J28: =IFERROR(AVERAGE(J29:J34),0) -> 0
A29: #VALUE! | B29: PESO (kg) | E29: PIEDE FORTE | F29: PIEDE DEBOLE | G29: FISICA | H29: =B36 -> 53.333333 | I29: =C36 -> 0 | J29: =D36 -> 0 | K29: =IFERROR(AVERAGEIF(H29:J29,">0"),0) -> 53.333333 | L29: =LEFT(G29,3) -> FIS
B30: =B5 -> 45778 | C30: =C5 -> 45901 | D30: =D5 -> 45992 | E30: =E5 -> Dx | F30: =F5 -> Sufficiente | G30: TATTICA | H30: =B44 -> 60 | I30: =C44 -> 0 | J30: =D44 -> 0 | K30: =IFERROR(AVERAGEIF(H30:J30,">0"),0) -> 60 | L30: =LEFT(G30,3) -> TAT
B31: =B6 -> 44 | C31: =C6 -> 0 | D31: =D6 -> 0 | E31: RUOLO | F31: ATTITUDINE | G31: TECNICA | H31: =H36 -> 60 | I31: =I36 -> 0 | J31: =J36 -> 0 | K31: =IFERROR(AVERAGEIF(H31:J31,">0"),0) -> 60 | L31: =LEFT(G31,3) -> TEC
B32: ALTEZZA (cm) | E32: =E7 -> Difensore | F32: =F7 -> Attacco | G32: PSICOLOGIA | H32: =H44 -> 58.333333 | I32: =I44 -> 0 | J32: =J44 -> 0 | K32: =IFERROR(AVERAGEIF(H32:J32,">0"),0) -> 58.333333 | L32: =LEFT(G32,3) -> PSI
B33: =B30 -> 45778 | C33: =C30 -> 45901 | D33: =D30 -> 45992 | E33: CORPORATURA | F33: MORFOLOGIA | G33: PESO | H33: =B31 -> 44 | I33: =C31 -> 0 | J33: =D31 -> 0 | K33: =IFERROR(AVERAGEIF(H33:J33,">0"),0) -> 44 | L33: =LEFT(G33,3) -> PES
B34: =B9 -> 158 | C34: =C9 -> 0 | D34: =D9 -> 0 | E34: =E9 -> Sottopeso | F34: =F9 -> Normolineo | G34: ALTEZZA | H34: =B34 -> 158 | I34: =C34 -> 0 | J34: =D34 -> 0 | K34: =IFERROR(AVERAGEIF(H34:J34,">0"),0)/2.65 -> 59.622642 | L34: =LEFT(G34,3) -> ALT
A35: VALUTAZIONE FISICA | B35: =B33 -> 45778 | C35: =C33 -> 45901 | D35: =D33 -> 45992 | E35: MEDIA | G35: VALUTAZIONE TECNICA | H35: =H27 -> 45778 | I35: =I27 -> 45901 | J35: =J27 -> 45992 | K35: MEDIA | L35: MEDIA
B36: =IFERROR(SUM(HLOOKUP(B37,BASEDATI!$C$4:$H$5,2,FALSE),HLOOKUP(B38,BASEDATI!$C$4:$H$5,2,FALSE),HLOOKUP(B39,BASEDATI!$C$4:$H$5,2,FALSE),HLOOKUP(B40,BASEDATI!$C$4:$H$5,2,FALSE),HLOOKUP(B41,BASEDATI!$C$4:$H$5,2,FALSE),HLOOKUP(B42,BASEDATI!$C$4:$H$5,2,FALSE))/COUNTA(B37:B42),0) -> 53.333333 | C36: =IFERROR(SUM(HLOOKUP(C37,BASEDATI!$C$4:$H$5,2,FALSE),HLOOKUP(C38,BASEDATI!$C$4:$H$5,2,FALSE),HLOOKUP(C39,BASEDATI!$C$4:$H$5,2,FALSE),HLOOKUP(C40,BASEDATI!$C$4:$H$5,2,FALSE),HLOOKUP(C41,BASEDATI!$C$4:$H$5,2,FALSE),HLOOKUP(C42,BASEDATI!$C$4:$H$5,2,FALSE))/COUNTA(C37:C42),0) -> 0 | D36: =IFERROR(SUM(HLOOKUP(D37,BASEDATI!$C$4:$H$5,2,FALSE),HLOOKUP(D38,BASEDATI!$C$4:$H$5,2,FALSE),HLOOKUP(D39,BASEDATI!$C$4:$H$5,2,FALSE),HLOOKUP(D40,BASEDATI!$C$4:$H$5,2,FALSE),HLOOKUP(D41,BASEDATI!$C$4:$H$5,2,FALSE),HLOOKUP(D42,BASEDATI!$C$4:$H$5,2,FALSE))/COUNTA(D37:D42),0) -> 0 | H36: =IFERROR(SUM(HLOOKUP(H37,BASEDATI!$C$4:$H$5,2,FALSE),HLOOKUP(H38,BASEDATI!$C$4:$H$5,2,FALSE),HLOOKUP(H39,BASEDATI!$C$4:$H$5,2,FALSE),HLOOKUP(H40,BASEDATI!$C$4:$H$5,2,FALSE),HLOOKUP(H41,BASEDATI!$C$4:$H$5,2,FALSE),HLOOKUP(H42,BASEDATI!$C$4:$H$5,2,FALSE))/COUNTA(H37:H42),0) -> 60 | I36: =IFERROR(SUM(HLOOKUP(I37,BASEDATI!$C$4:$H$5,2,FALSE),HLOOKUP(I38,BASEDATI!$C$4:$H$5,2,FALSE),HLOOKUP(I39,BASEDATI!$C$4:$H$5,2,FALSE),HLOOKUP(I40,BASEDATI!$C$4:$H$5,2,FALSE),HLOOKUP(I41,BASEDATI!$C$4:$H$5,2,FALSE),HLOOKUP(I42,BASEDATI!$C$4:$H$5,2,FALSE))/COUNTA(I37:I42),0) -> 0 | J36: =IFERROR(SUM(HLOOKUP(J37,BASEDATI!$C$4:$H$5,2,FALSE),HLOOKUP(J38,BASEDATI!$C$4:$H$5,2,FALSE),HLOOKUP(J39,BASEDATI!$C$4:$H$5,2,FALSE),HLOOKUP(J40,BASEDATI!$C$4:$H$5,2,FALSE),HLOOKUP(J41,BASEDATI!$C$4:$H$5,2,FALSE),HLOOKUP(J42,BASEDATI!$C$4:$H$5,2,FALSE))/COUNTA(J37:J42),0) -> 0
A37: Forza | B37: InsufficIente | E37: =SUM(IFERROR(HLOOKUP(B37,BASEDATI!$C$4:$H$5,2,FALSE),0),IFERROR(HLOOKUP(C37,BASEDATI!$C$4:$H$5,2,FALSE),0),IFERROR(HLOOKUP(D37,BASEDATI!$C$4:$H$5,2,FALSE),0))/COUNTA(B37:D37) -> 50 | F37: =LEFT(A37,3) -> For | G37: Guida e difesa palla | H37: Sufficiente | K37: =SUM(IFERROR(HLOOKUP(H37,BASEDATI!$C$4:$H$5,2,FALSE),0),IFERROR(HLOOKUP(I37,BASEDATI!$C$4:$H$5,2,FALSE),0),IFERROR(HLOOKUP(J37,BASEDATI!$C$4:$H$5,2,FALSE),0))/COUNTA(H37:J37) -> 60 | L37: =LEFT(G37,3) -> Gui
A38: Velocità | B38: InsufficIente | E38: =SUM(IFERROR(HLOOKUP(B38,BASEDATI!$C$4:$H$5,2,FALSE),0),IFERROR(HLOOKUP(C38,BASEDATI!$C$4:$H$5,2,FALSE),0),IFERROR(HLOOKUP(D38,BASEDATI!$C$4:$H$5,2,FALSE),0))/COUNTA(B38:D38) -> 50 | F38: =LEFT(A38,3) -> Vel | G38: Contrasto | H38: Sufficiente | K38: =SUM(IFERROR(HLOOKUP(H38,BASEDATI!$C$4:$H$5,2,FALSE),0),IFERROR(HLOOKUP(I38,BASEDATI!$C$4:$H$5,2,FALSE),0),IFERROR(HLOOKUP(J38,BASEDATI!$C$4:$H$5,2,FALSE),0))/COUNTA(H38:J38) -> 60 | L38: =LEFT(G38,3) -> Con
A39: Resistenza | B39: InsufficIente | E39: =SUM(IFERROR(HLOOKUP(B39,BASEDATI!$C$4:$H$5,2,FALSE),0),IFERROR(HLOOKUP(C39,BASEDATI!$C$4:$H$5,2,FALSE),0),IFERROR(HLOOKUP(D39,BASEDATI!$C$4:$H$5,2,FALSE),0))/COUNTA(B39:D39) -> 50 | F39: =LEFT(A39,3) -> Res | G39: Controllo orientato | H39: Sufficiente | K39: =SUM(IFERROR(HLOOKUP(H39,BASEDATI!$C$4:$H$5,2,FALSE),0),IFERROR(HLOOKUP(I39,BASEDATI!$C$4:$H$5,2,FALSE),0),IFERROR(HLOOKUP(J39,BASEDATI!$C$4:$H$5,2,FALSE),0))/COUNTA(H39:J39) -> 60 | L39: =LEFT(G39,3) -> Con
A40: Coordinazione | B40: Buono | E40: =SUM(IFERROR(HLOOKUP(B40,BASEDATI!$C$4:$H$5,2,FALSE),0),IFERROR(HLOOKUP(C40,BASEDATI!$C$4:$H$5,2,FALSE),0),IFERROR(HLOOKUP(D40,BASEDATI!$C$4:$H$5,2,FALSE),0))/COUNTA(B40:D40) -> 70 | F40: =LEFT(A40,3) -> Coo | G40: Tiro in porta | H40: Sufficiente | K40: =SUM(IFERROR(HLOOKUP(H40,BASEDATI!$C$4:$H$5,2,FALSE),0),IFERROR(HLOOKUP(I40,BASEDATI!$C$4:$H$5,2,FALSE),0),IFERROR(HLOOKUP(J40,BASEDATI!$C$4:$H$5,2,FALSE),0))/COUNTA(H40:J40) -> 60 | L40: =LEFT(G40,3) -> Tir
...

Sheet DAIFI Rayane
A1: SCHEDA DI AUTOVALUTAZIONE PERFORMANCE
A2: DAIDI RAYANE | E2: D.NASCITA | F2: STAGIONE | G2: VALUTAZIONE GENERALE | H2: =B5 -> 45778 | I2: =C8 -> 45901 | J2: =D8 -> 45992 | K2: MEDIA
E3: 41217 | F3: 2025/2026 | H3: =IFERROR(AVERAGE(H4:H9),0) -> 0 | I3: =IFERROR(AVERAGE(I4:I9),0) -> 0 | J3: =IFERROR(AVERAGE(J4:J9),0) -> 33.45
B4: PESO (kg) | E4: PIEDE FORTE | F4: PIEDE DEBOLE | G4: FISICA | H4: =B11 -> 0 | I4: =C11 -> 0 | J4: =D11 -> 0 | K4: =IFERROR(AVERAGEIF(H4:J4,">0"),0) -> 0 | L4: =LEFT(G4,3) -> FIS
B5: 45778 | C5: 45901 | D5: 45992 | E5: Dx | F5: Sufficiente | G5: TATTICA | H5: =B19 -> 0 | I5: =C19 -> 0 | J5: =D19 -> 0 | K5: =IFERROR(AVERAGEIF(H5:J5,">0"),0) -> 0 | L5: =LEFT(G5,3) -> TAT
D6: 42.7 | E6: RUOLO | F6: ATTITUDINE | G6: TECNICA | H6: =H11 -> 0 | I6: =I11 -> 0 | J6: =J11 -> 0 | K6: =IFERROR(AVERAGEIF(H6:J6,">0"),0) -> 0 | L6: =LEFT(G6,3) -> TEC
B7: ALTEZZA (cm) | F7: Attacco | G7: PSICOLOGIA | H7: =H19 -> 0 | I7: =I19 -> 0 | J7: =J19 -> 0 | K7: =IFERROR(AVERAGEIF(H7:J7,">0"),0) -> 0 | L7: =LEFT(G7,3) -> PSI
B8: =B5 -> 45778 | C8: =C5 -> 45901 | D8: =D5 -> 45992 | E8: CORPORATURA | F8: MORFOLOGIA | G8: PESO | H8: =B6 -> 0 | I8: =C6 -> 0 | J8: =D6 -> 42.7 | K8: =IFERROR(AVERAGEIF(H8:J8,">0"),0) -> 42.7 | L8: =LEFT(G8,3) -> PES
D9: 158 | E9: Normale | F9: Normolineo | G9: ALTEZZA | H9: =B9 -> 0 | I9: =C9 -> 0 | J9: =D9 -> 158 | K9: =IFERROR(AVERAGEIF(H9:J9,">0"),0)/2.65 -> 59.622642 | L9: =LEFT(G9,3) -> ALT
A10: VALUTAZIONE FISICA | B10: =B8 -> 45778 | C10: =C8 -> 45901 | D10: =D8 -> 45992 | E10: MEDIA | G10: VALUTAZIONE TECNICA | H10: =H2 -> 45778 | I10: =I2 -> 45901 | J10: =J2 -> 45992 | K10: MEDIA
B11: =IFERROR(SUM(HLOOKUP(B12,BASEDATI!$C$4:$H$5,2,FALSE),HLOOKUP(B13,BASEDATI!$C$4:$H$5,2,FALSE),HLOOKUP(B14,BASEDATI!$C$4:$H$5,2,FALSE),HLOOKUP(B15,BASEDATI!$C$4:$H$5,2,FALSE),HLOOKUP(B16,BASEDATI!$C$4:$H$5,2,FALSE),HLOOKUP(B17,BASEDATI!$C$4:$H$5,2,FALSE))/COUNTA(B12:B17),0) -> 0 | C11: =IFERROR(SUM(HLOOKUP(C12,BASEDATI!$C$4:$H$5,2,FALSE),HLOOKUP(C13,BASEDATI!$C$4:$H$5,2,FALSE),HLOOKUP(C14,BASEDATI!$C$4:$H$5,2,FALSE),HLOOKUP(C15,BASEDATI!$C$4:$H$5,2,FALSE),HLOOKUP(C16,BASEDATI!$C$4:$H$5,2,FALSE),HLOOKUP(C17,BASEDATI!$C$4:$H$5,2,FALSE))/COUNTA(C12:C17),0) -> 0 | D11: =IFERROR(SUM(HLOOKUP(D12,BASEDATI!$C$4:$H$5,2,FALSE),HLOOKUP(D13,BASEDATI!$C$4:$H$5,2,FALSE),HLOOKUP(D14,BASEDATI!$C$4:$H$5,2,FALSE),HLOOKUP(D15,BASEDATI!$C$4:$H$5,2,FALSE),HLOOKUP(D16,BASEDATI!$C$4:$H$5,2,FALSE),HLOOKUP(D17,BASEDATI!$C$4:$H$5,2,FALSE))/COUNTA(D12:D17),0) -> 0 | H11: =IFERROR(SUM(HLOOKUP(H12,BASEDATI!$C$4:$H$5,2,FALSE),HLOOKUP(H13,BASEDATI!$C$4:$H$5,2,FALSE),HLOOKUP(H14,BASEDATI!$C$4:$H$5,2,FALSE),HLOOKUP(H15,BASEDATI!$C$4:$H$5,2,FALSE),HLOOKUP(H16,BASEDATI!$C$4:$H$5,2,FALSE),HLOOKUP(H17,BASEDATI!$C$4:$H$5,2,FALSE))/COUNTA(H12:H17),0) -> 0 | I11: =IFERROR(SUM(HLOOKUP(I12,BASEDATI!$C$4:$H$5,2,FALSE),HLOOKUP(I13,BASEDATI!$C$4:$H$5,2,FALSE),HLOOKUP(I14,BASEDATI!$C$4:$H$5,2,FALSE),HLOOKUP(I15,BASEDATI!$C$4:$H$5,2,FALSE),HLOOKUP(I16,BASEDATI!$C$4:$H$5,2,FALSE),HLOOKUP(I17,BASEDATI!$C$4:$H$5,2,FALSE))/COUNTA(I12:I17),0) -> 0 | J11: =IFERROR(SUM(HLOOKUP(J12,BASEDATI!$C$4:$H$5,2,FALSE),HLOOKUP(J13,BASEDATI!$C$4:$H$5,2,FALSE),HLOOKUP(J14,BASEDATI!$C$4:$H$5,2,FALSE),HLOOKUP(J15,BASEDATI!$C$4:$H$5,2,FALSE),HLOOKUP(J16,BASEDATI!$C$4:$H$5,2,FALSE),HLOOKUP(J17,BASEDATI!$C$4:$H$5,2,FALSE))/COUNTA(J12:J17),0) -> 0
A12: Forza | E12: =SUM(IFERROR(HLOOKUP(B12,BASEDATI!$C$4:$H$5,2,FALSE),0),IFERROR(HLOOKUP(C12,BASEDATI!$C$4:$H$5,2,FALSE),0),IFERROR(HLOOKUP(D12,BASEDATI!$C$4:$H$5,2,FALSE),0))/COUNTA(B12:D12) -> #DIV/0! | F12: =LEFT(A12,3) -> For | G12: Guida e difesa palla | K12: =SUM(IFERROR(HLOOKUP(H12,BASEDATI!$C$4:$H$5,2,FALSE),0),IFERROR(HLOOKUP(I12,BASEDATI!$C$4:$H$5,2,FALSE),0),IFERROR(HLOOKUP(J12,BASEDATI!$C$4:$H$5,2,FALSE),0))/COUNTA(H12:J12) -> #DIV/0! | L12: =LEFT(G12,3) -> Gui
A13: Velocità | E13: =SUM(IFERROR(HLOOKUP(B13,BASEDATI!$C$4:$H$5,2,FALSE),0),IFERROR(HLOOKUP(C13,BASEDATI!$C$4:$H$5,2,FALSE),0),IFERROR(HLOOKUP(D13,BASEDATI!$C$4:$H$5,2,FALSE),0))/COUNTA(B13:D13) -> #DIV/0! | F13: =LEFT(A13,3) -> Vel | G13: Contrasto | K13: =SUM(IFERROR(HLOOKUP(H13,BASEDATI!$C$4:$H$5,2,FALSE),0),IFERROR(HLOOKUP(I13,BASEDATI!$C$4:$H$5,2,FALSE),0),IFERROR(HLOOKUP(J13,BASEDATI!$C$4:$H$5,2,FALSE),0))/COUNTA(H13:J13) -> #DIV/0! | L13: =LEFT(G13,3) -> Con
A14: Resistenza | E14: =SUM(IFERROR(HLOOKUP(B14,BASEDATI!$C$4:$H$5,2,FALSE),0),IFERROR(HLOOKUP(C14,BASEDATI!$C$4:$H$5,2,FALSE),0),IFERROR(HLOOKUP(D14,BASEDATI!$C$4:$H$5,2,FALSE),0))/COUNTA(B14:D14) -> #DIV/0! | F14: =LEFT(A14,3) -> Res | G14: Controllo orientato | K14: =SUM(IFERROR(HLOOKUP(H14,BASEDATI!$C$4:$H$5,2,FALSE),0),IFERROR(HLOOKUP(I14,BASEDATI!$C$4:$H$5,2,FALSE),0),IFERROR(HLOOKUP(J14,BASEDATI!$C$4:$H$5,2,FALSE),0))/COUNTA(H14:J14) -> #DIV/0! | L14: =LEFT(G14,3) -> Con
A15: Coordinazione | E15: =SUM(IFERROR(HLOOKUP(B15,BASEDATI!$C$4:$H$5,2,FALSE),0),IFERROR(HLOOKUP(C15,BASEDATI!$C$4:$H$5,2,FALSE),0),IFERROR(HLOOKUP(D15,BASEDATI!$C$4:$H$5,2,FALSE),0))/COUNTA(B15:D15) -> #DIV/0! | F15: =LEFT(A15,3) -> Coo | G15: Tiro in porta | K15: =SUM(IFERROR(HLOOKUP(H15,BASEDATI!$C$4:$H$5,2,FALSE),0),IFERROR(HLOOKUP(I15,BASEDATI!$C$4:$H$5,2,FALSE),0),IFERROR(HLOOKUP(J15,BASEDATI!$C$4:$H$5,2,FALSE),0))/COUNTA(H15:J15) -> #DIV/0! | L15: =LEFT(G15,3) -> Tir
A16: Rapidità | E16: =SUM(IFERROR(HLOOKUP(B16,BASEDATI!$C$4:$H$5,2,FALSE),0),IFERROR(HLOOKUP(C16,BASEDATI!$C$4:$H$5,2,FALSE),0),IFERROR(HLOOKUP(D16,BASEDATI!$C$4:$H$5,2,FALSE),0))/COUNTA(B16:D16) -> #DIV/0! | F16: =LEFT(A16,3) -> Rap | G16: Uno contro uno | K16: =SUM(IFERROR(HLOOKUP(H16,BASEDATI!$C$4:$H$5,2,FALSE),0),IFERROR(HLOOKUP(I16,BASEDATI!$C$4:$H$5,2,FALSE),0),IFERROR(HLOOKUP(J16,BASEDATI!$C$4:$H$5,2,FALSE),0))/COUNTA(H16:J16) -> #DIV/0! | L16: =LEFT(G16,3) -> Uno
A17: Recupero | E17: =SUM(IFERROR(HLOOKUP(B17,BASEDATI!$C$4:$H$5,2,FALSE),0),IFERROR(HLOOKUP(C17,BASEDATI!$C$4:$H$5,2,FALSE),0),IFERROR(HLOOKUP(D17,BASEDATI!$C$4:$H$5,2,FALSE),0))/COUNTA(B17:D17) -> #DIV/0! | F17: =LEFT(A17,3) -> Rec | G17: Uso piede debole | K17: =SUM(IFERROR(HLOOKUP(H17,BASEDATI!$C$4:$H$5,2,FALSE),0),IFERROR(HLOOKUP(I17,BASEDATI!$C$4:$H$5,2,FALSE),0),IFERROR(HLOOKUP(J17,BASEDATI!$C$4:$H$5,2,FALSE),0))/COUNTA(H17:J17) -> #DIV/0! | L17: =LEFT(G17,3) -> Uso
A18: VALUTAZIONE TATTICA | B18: =B10 -> 45778 | C18: =C10 -> 45901 | D18: =D10 -> 45992 | E18: MEDIA | G18: VALUTAZIONE PISICOLOGICA | H18: =H10 -> 45778 | I18: =I10 -> 45901 | J18: =J10 -> 45992 | K18: MEDIA
